/Users/david/python-microscopy/doc/BasicAcquisition.rst:4: ERROR: Unknown target name: "advancedimaging".
/Users/david/python-microscopy/doc/BasicAcquisition.rst:29: ERROR: Unknown target name: "shiftfield".
/Users/david/python-microscopy/doc/BasicAcquisition.rst:31: ERROR: Unknown target name: "advancedimaging".
/Users/david/python-microscopy/doc/Installation/InstallationFromSource.rst:107: WARNING: Literal block ends without a blank line; unexpected unindent.
/Users/david/python-microscopy/doc/Recipes.rst:28: WARNING: Inline literal start-string without end-string.
/Users/david/python-microscopy/doc/SampleDB.rst:20: ERROR: Unexpected indentation.
/Users/david/python-microscopy/doc/SampleDB.rst:32: ERROR: Unexpected indentation.
/Users/david/python-microscopy/doc/SampleDB.rst:38: ERROR: Unexpected indentation.
/Users/david/python-microscopy/doc/SampleDB.rst:44: ERROR: Unexpected indentation.
/Users/david/python-microscopy/doc/SampleDB.rst:66: ERROR: Unexpected indentation.
/Users/david/python-microscopy/doc/SampleDB.rst:70: ERROR: Unexpected indentation.
/Users/david/python-microscopy/doc/SampleDB.rst:87: ERROR: Unexpected indentation.
/Users/david/python-microscopy/doc/SplitterMulticolour.rst:29: WARNING: Enumerated list ends without a blank line; unexpected unindent.
/Users/david/python-microscopy/doc/Technical.rst:4: WARNING: toctree contains reference to nonexisting document u'FitModules'
/Users/david/python-microscopy/doc/api/Acquire/Hardware/PYME.Acquire.Hardware.rst:7: WARNING: toctree contains reference to nonexisting document u'api/Acquire/Hardware/PYME.Acquire.Hardware.Old'
/Users/david/python-microscopy/doc/api/Acquire/Hardware/PYME.Acquire.Hardware.AndorIXon.AndorCam.rst:4: WARNING: autodoc: failed to import module u'PYME.Acquire.Hardware.AndorIXon.AndorCam'; the following exception was raised:
Traceback (most recent call last):
  File "/Users/david/anaconda/lib/python2.7/site-packages/Sphinx-1.3.1-py2.7.egg/sphinx/ext/autodoc.py", line 385, in import_object
    __import__(self.modname)
  File "/Users/david/python-microscopy/PYME/Acquire/Hardware/AndorIXon/AndorCam.py", line 40, in <module>
    _stdcall_libraries['ATMCD32D'] = CDLL('libandor.so')
  File "/Users/david/anaconda/lib/python2.7/ctypes/__init__.py", line 365, in __init__
    self._handle = _dlopen(self._name, mode)
OSError: dlopen(libandor.so, 6): image not found
/Users/david/python-microscopy/doc/api/Acquire/Hardware/PYME.Acquire.Hardware.AndorIXon.AndorIXon.rst:4: WARNING: autodoc: failed to import module u'PYME.Acquire.Hardware.AndorIXon.AndorIXon'; the following exception was raised:
Traceback (most recent call last):
  File "/Users/david/anaconda/lib/python2.7/site-packages/Sphinx-1.3.1-py2.7.egg/sphinx/ext/autodoc.py", line 385, in import_object
    __import__(self.modname)
  File "/Users/david/python-microscopy/PYME/Acquire/Hardware/AndorIXon/AndorIXon.py", line 24, in <module>
    from . import AndorCam as ac
  File "/Users/david/python-microscopy/PYME/Acquire/Hardware/AndorIXon/AndorCam.py", line 40, in <module>
    _stdcall_libraries['ATMCD32D'] = CDLL('libandor.so')
  File "/Users/david/anaconda/lib/python2.7/ctypes/__init__.py", line 365, in __init__
    self._handle = _dlopen(self._name, mode)
OSError: dlopen(libandor.so, 6): image not found
/Users/david/python-microscopy/doc/api/Acquire/Hardware/PYME.Acquire.Hardware.AndorNeo.AndorNeo.rst:4: WARNING: autodoc: failed to import module u'PYME.Acquire.Hardware.AndorNeo.AndorNeo'; the following exception was raised:
Traceback (most recent call last):
  File "/Users/david/anaconda/lib/python2.7/site-packages/Sphinx-1.3.1-py2.7.egg/sphinx/ext/autodoc.py", line 385, in import_object
    __import__(self.modname)
  File "/Users/david/python-microscopy/PYME/Acquire/Hardware/AndorNeo/AndorNeo.py", line 25, in <module>
    from .SDK3Cam import *
  File "/Users/david/python-microscopy/PYME/Acquire/Hardware/AndorNeo/SDK3Cam.py", line 25, in <module>
    from .import SDK3
  File "/Users/david/python-microscopy/PYME/Acquire/Hardware/AndorNeo/SDK3.py", line 41, in <module>
    _stdcall_libraries['ATCORE'] = ctypes.CDLL('atcore.so')
  File "/Users/david/anaconda/lib/python2.7/ctypes/__init__.py", line 365, in __init__
    self._handle = _dlopen(self._name, mode)
OSError: dlopen(atcore.so, 6): image not found
/Users/david/python-microscopy/doc/api/Acquire/Hardware/PYME.Acquire.Hardware.AndorNeo.AndorZyla.rst:4: WARNING: autodoc: failed to import module u'PYME.Acquire.Hardware.AndorNeo.AndorZyla'; the following exception was raised:
Traceback (most recent call last):
  File "/Users/david/anaconda/lib/python2.7/site-packages/Sphinx-1.3.1-py2.7.egg/sphinx/ext/autodoc.py", line 385, in import_object
    __import__(self.modname)
  File "/Users/david/python-microscopy/PYME/Acquire/Hardware/AndorNeo/AndorZyla.py", line 25, in <module>
    from .SDK3Cam import *
  File "/Users/david/python-microscopy/PYME/Acquire/Hardware/AndorNeo/SDK3Cam.py", line 25, in <module>
    from .import SDK3
  File "/Users/david/python-microscopy/PYME/Acquire/Hardware/AndorNeo/SDK3.py", line 41, in <module>
    _stdcall_libraries['ATCORE'] = ctypes.CDLL('atcore.so')
  File "/Users/david/anaconda/lib/python2.7/ctypes/__init__.py", line 365, in __init__
    self._handle = _dlopen(self._name, mode)
OSError: dlopen(atcore.so, 6): image not found
/Users/david/python-microscopy/doc/api/Acquire/Hardware/PYME.Acquire.Hardware.AndorNeo.SDK3.rst:4: WARNING: autodoc: failed to import module u'PYME.Acquire.Hardware.AndorNeo.SDK3'; the following exception was raised:
Traceback (most recent call last):
  File "/Users/david/anaconda/lib/python2.7/site-packages/Sphinx-1.3.1-py2.7.egg/sphinx/ext/autodoc.py", line 385, in import_object
    __import__(self.modname)
  File "/Users/david/python-microscopy/PYME/Acquire/Hardware/AndorNeo/SDK3.py", line 41, in <module>
    _stdcall_libraries['ATCORE'] = ctypes.CDLL('atcore.so')
  File "/Users/david/anaconda/lib/python2.7/ctypes/__init__.py", line 365, in __init__
    self._handle = _dlopen(self._name, mode)
OSError: dlopen(atcore.so, 6): image not found
/Users/david/python-microscopy/doc/api/Acquire/Hardware/PYME.Acquire.Hardware.AndorNeo.SDK3Cam.rst:4: WARNING: autodoc: failed to import module u'PYME.Acquire.Hardware.AndorNeo.SDK3Cam'; the following exception was raised:
Traceback (most recent call last):
  File "/Users/david/anaconda/lib/python2.7/site-packages/Sphinx-1.3.1-py2.7.egg/sphinx/ext/autodoc.py", line 385, in import_object
    __import__(self.modname)
  File "/Users/david/python-microscopy/PYME/Acquire/Hardware/AndorNeo/SDK3Cam.py", line 25, in <module>
    from .import SDK3
  File "/Users/david/python-microscopy/PYME/Acquire/Hardware/AndorNeo/SDK3.py", line 41, in <module>
    _stdcall_libraries['ATCORE'] = ctypes.CDLL('atcore.so')
  File "/Users/david/anaconda/lib/python2.7/ctypes/__init__.py", line 365, in __init__
    self._handle = _dlopen(self._name, mode)
OSError: dlopen(atcore.so, 6): image not found
/Users/david/python-microscopy/doc/api/Acquire/Hardware/PYME.Acquire.Hardware.AndorNeo.testNeo.rst:4: WARNING: autodoc: failed to import module u'PYME.Acquire.Hardware.AndorNeo.testNeo'; the following exception was raised:
Traceback (most recent call last):
  File "/Users/david/anaconda/lib/python2.7/site-packages/Sphinx-1.3.1-py2.7.egg/sphinx/ext/autodoc.py", line 385, in import_object
    __import__(self.modname)
  File "/Users/david/python-microscopy/PYME/Acquire/Hardware/AndorNeo/testNeo.py", line 26, in <module>
    import AndorNeo
  File "/Users/david/python-microscopy/PYME/Acquire/Hardware/AndorNeo/AndorNeo.py", line 25, in <module>
    from .SDK3Cam import *
  File "/Users/david/python-microscopy/PYME/Acquire/Hardware/AndorNeo/SDK3Cam.py", line 25, in <module>
    from .import SDK3
  File "/Users/david/python-microscopy/PYME/Acquire/Hardware/AndorNeo/SDK3.py", line 41, in <module>
    _stdcall_libraries['ATCORE'] = ctypes.CDLL('atcore.so')
  File "/Users/david/anaconda/lib/python2.7/ctypes/__init__.py", line 365, in __init__
    self._handle = _dlopen(self._name, mode)
OSError: dlopen(atcore.so, 6): image not found
/Users/david/python-microscopy/doc/api/Acquire/Hardware/PYME.Acquire.Hardware.DigiData.DigiData.rst:4: WARNING: autodoc: failed to import module u'PYME.Acquire.Hardware.DigiData.DigiData'; the following exception was raised:
Traceback (most recent call last):
  File "/Users/david/anaconda/lib/python2.7/site-packages/Sphinx-1.3.1-py2.7.egg/sphinx/ext/autodoc.py", line 385, in import_object
    __import__(self.modname)
  File "/Users/david/python-microscopy/PYME/Acquire/Hardware/DigiData/DigiData.py", line 24, in <module>
    from .axDD132x import *
  File "/Users/david/python-microscopy/PYME/Acquire/Hardware/DigiData/axDD132x.py", line 26, in <module>
    from ctypes.wintypes import UINT
  File "/Users/david/anaconda/lib/python2.7/ctypes/wintypes.py", line 23, in <module>
    class VARIANT_BOOL(_SimpleCData):
ValueError: _type_ 'v' not supported
/Users/david/python-microscopy/doc/api/Acquire/Hardware/PYME.Acquire.Hardware.DigiData.RemoteDigiData.rst:4: WARNING: autodoc: failed to import module u'PYME.Acquire.Hardware.DigiData.RemoteDigiData'; the following exception was raised:
Traceback (most recent call last):
  File "/Users/david/anaconda/lib/python2.7/site-packages/Sphinx-1.3.1-py2.7.egg/sphinx/ext/autodoc.py", line 385, in import_object
    __import__(self.modname)
  File "/Users/david/python-microscopy/PYME/Acquire/Hardware/DigiData/RemoteDigiData.py", line 25, in <module>
    from .DigiData import *
  File "/Users/david/python-microscopy/PYME/Acquire/Hardware/DigiData/DigiData.py", line 24, in <module>
    from .axDD132x import *
  File "/Users/david/python-microscopy/PYME/Acquire/Hardware/DigiData/axDD132x.py", line 26, in <module>
    from ctypes.wintypes import UINT
  File "/Users/david/anaconda/lib/python2.7/ctypes/wintypes.py", line 23, in <module>
    class VARIANT_BOOL(_SimpleCData):
ValueError: _type_ 'v' not supported
/Users/david/python-microscopy/doc/api/Acquire/Hardware/PYME.Acquire.Hardware.DigiData.axDD132x.rst:4: WARNING: autodoc: failed to import module u'PYME.Acquire.Hardware.DigiData.axDD132x'; the following exception was raised:
Traceback (most recent call last):
  File "/Users/david/anaconda/lib/python2.7/site-packages/Sphinx-1.3.1-py2.7.egg/sphinx/ext/autodoc.py", line 385, in import_object
    __import__(self.modname)
  File "/Users/david/python-microscopy/PYME/Acquire/Hardware/DigiData/axDD132x.py", line 26, in <module>
    from ctypes.wintypes import UINT
  File "/Users/david/anaconda/lib/python2.7/ctypes/wintypes.py", line 23, in <module>
    class VARIANT_BOOL(_SimpleCData):
ValueError: _type_ 'v' not supported
/Users/david/python-microscopy/doc/api/Acquire/Hardware/PYME.Acquire.Hardware.FocCorrR.rst:4: WARNING: autodoc: failed to import module u'PYME.Acquire.Hardware.FocCorrR'; the following exception was raised:
Traceback (most recent call last):
  File "/Users/david/anaconda/lib/python2.7/site-packages/Sphinx-1.3.1-py2.7.egg/sphinx/ext/autodoc.py", line 385, in import_object
    __import__(self.modname)
  File "/Users/david/python-microscopy/PYME/Acquire/Hardware/FocCorrR.py", line 27, in <module>
    import eventLog
ImportError: No module named eventLog
/Users/david/python-microscopy/doc/api/Acquire/Hardware/PYME.Acquire.Hardware.Mercury.Mercury.rst:4: WARNING: autodoc: failed to import module u'PYME.Acquire.Hardware.Mercury.Mercury'; the following exception was raised:
Traceback (most recent call last):
  File "/Users/david/anaconda/lib/python2.7/site-packages/Sphinx-1.3.1-py2.7.egg/sphinx/ext/autodoc.py", line 385, in import_object
    __import__(self.modname)
  File "/Users/david/python-microscopy/PYME/Acquire/Hardware/Mercury/Mercury.py", line 23, in <module>
    from . import PI_Mercury_GCS_DLL as mc
  File "/Users/david/python-microscopy/PYME/Acquire/Hardware/Mercury/PI_Mercury_GCS_DLL.py", line 27, in <module>
    _stdcall_libraries['PI_Mercury_GCS_DLL.dll'] = WinDLL('PI_Mercury_GCS_DLL.dll')
NameError: name 'WinDLL' is not defined
/Users/david/python-microscopy/doc/api/Acquire/Hardware/PYME.Acquire.Hardware.Mercury.PI_Mercury_GCS_DLL.rst:4: WARNING: autodoc: failed to import module u'PYME.Acquire.Hardware.Mercury.PI_Mercury_GCS_DLL'; the following exception was raised:
Traceback (most recent call last):
  File "/Users/david/anaconda/lib/python2.7/site-packages/Sphinx-1.3.1-py2.7.egg/sphinx/ext/autodoc.py", line 385, in import_object
    __import__(self.modname)
  File "/Users/david/python-microscopy/PYME/Acquire/Hardware/Mercury/PI_Mercury_GCS_DLL.py", line 27, in <module>
    _stdcall_libraries['PI_Mercury_GCS_DLL.dll'] = WinDLL('PI_Mercury_GCS_DLL.dll')
NameError: name 'WinDLL' is not defined
/Users/david/python-microscopy/doc/api/Acquire/Hardware/PYME.Acquire.Hardware.Mercury.mercuryStepper.rst:4: WARNING: autodoc: failed to import module u'PYME.Acquire.Hardware.Mercury.mercuryStepper'; the following exception was raised:
Traceback (most recent call last):
  File "/Users/david/anaconda/lib/python2.7/site-packages/Sphinx-1.3.1-py2.7.egg/sphinx/ext/autodoc.py", line 385, in import_object
    __import__(self.modname)
  File "/Users/david/python-microscopy/PYME/Acquire/Hardware/Mercury/mercuryStepper.py", line 24, in <module>
    from . import Mercury as m
  File "/Users/david/python-microscopy/PYME/Acquire/Hardware/Mercury/Mercury.py", line 23, in <module>
    from . import PI_Mercury_GCS_DLL as mc
  File "/Users/david/python-microscopy/PYME/Acquire/Hardware/Mercury/PI_Mercury_GCS_DLL.py", line 27, in <module>
    _stdcall_libraries['PI_Mercury_GCS_DLL.dll'] = WinDLL('PI_Mercury_GCS_DLL.dll')
NameError: name 'WinDLL' is not defined
/Users/david/python-microscopy/doc/api/Acquire/Hardware/PYME.Acquire.Hardware.NikonTE2000.rst:4: WARNING: autodoc: failed to import module u'PYME.Acquire.Hardware.NikonTE2000'; the following exception was raised:
Traceback (most recent call last):
  File "/Users/david/anaconda/lib/python2.7/site-packages/Sphinx-1.3.1-py2.7.egg/sphinx/ext/autodoc.py", line 385, in import_object
    __import__(self.modname)
  File "/Users/david/python-microscopy/PYME/Acquire/Hardware/NikonTE2000.py", line 28, in <module>
    import win32com.client
ImportError: No module named win32com.client
/Users/david/python-microscopy/doc/api/Acquire/Hardware/PYME.Acquire.Hardware.NikonTi.rst:4: WARNING: autodoc: failed to import module u'PYME.Acquire.Hardware.NikonTi'; the following exception was raised:
Traceback (most recent call last):
  File "/Users/david/anaconda/lib/python2.7/site-packages/Sphinx-1.3.1-py2.7.egg/sphinx/ext/autodoc.py", line 385, in import_object
    __import__(self.modname)
  File "/Users/david/python-microscopy/PYME/Acquire/Hardware/NikonTi.py", line 28, in <module>
    import win32com.client
ImportError: No module named win32com.client
/Users/david/python-microscopy/doc/api/Acquire/Hardware/PYME.Acquire.Hardware.PM100USB.rst:4: WARNING: autodoc: failed to import module u'PYME.Acquire.Hardware.PM100USB'; the following exception was raised:
Traceback (most recent call last):
  File "/Users/david/anaconda/lib/python2.7/site-packages/Sphinx-1.3.1-py2.7.egg/sphinx/ext/autodoc.py", line 385, in import_object
    __import__(self.modname)
  File "/Users/david/python-microscopy/PYME/Acquire/Hardware/PM100USB.py", line 23, in <module>
    import visa
ImportError: No module named visa
/Users/david/python-microscopy/doc/api/Acquire/Hardware/PYME.Acquire.Hardware.Piezos.piezo_test.rst:4: WARNING: autodoc: failed to import module u'PYME.Acquire.Hardware.Piezos.piezo_test'; the following exception was raised:
Traceback (most recent call last):
  File "/Users/david/anaconda/lib/python2.7/site-packages/Sphinx-1.3.1-py2.7.egg/sphinx/ext/autodoc.py", line 385, in import_object
    __import__(self.modname)
  File "/Users/david/python-microscopy/PYME/Acquire/Hardware/Piezos/piezo_test.py", line 25, in <module>
    import scipy.plt
ImportError: No module named plt
/Users/david/python-microscopy/doc/api/Acquire/Hardware/PYME.Acquire.Hardware.Simulator.dSimControl.rst:4: WARNING: autodoc: failed to import module u'PYME.Acquire.Hardware.Simulator.dSimControl'; the following exception was raised:
Traceback (most recent call last):
  File "/Users/david/anaconda/lib/python2.7/site-packages/Sphinx-1.3.1-py2.7.egg/sphinx/ext/autodoc.py", line 385, in import_object
    __import__(self.modname)
  File "/Users/david/python-microscopy/PYME/Acquire/Hardware/Simulator/dSimControl.py", line 28, in <module>
    from . import fluor
  File "/Users/david/python-microscopy/PYME/Acquire/Hardware/Simulator/fluor.py", line 28, in <module>
    from . import illuminate
  File "numpy.pxd", line 155, in init PYME.Acquire.Hardware.Simulator.illuminate (PYME/Acquire/Hardware/Simulator/illuminate.c:4449)
TypeError: numpy.dtype is not a type object
/Users/david/python-microscopy/doc/api/Acquire/Hardware/PYME.Acquire.Hardware.Simulator.fakeCam.rst:4: WARNING: autodoc: failed to import module u'PYME.Acquire.Hardware.Simulator.fakeCam'; the following exception was raised:
Traceback (most recent call last):
  File "/Users/david/anaconda/lib/python2.7/site-packages/Sphinx-1.3.1-py2.7.egg/sphinx/ext/autodoc.py", line 385, in import_object
    __import__(self.modname)
  File "/Users/david/python-microscopy/PYME/Acquire/Hardware/Simulator/fakeCam.py", line 24, in <module>
    from . import rend_im
  File "/Users/david/python-microscopy/PYME/Acquire/Hardware/Simulator/rend_im.py", line 101, in <module>
    genTheoreticalModel(MetaData.TIRFDefault)
  File "/Users/david/python-microscopy/PYME/Acquire/Hardware/Simulator/rend_im.py", line 82, in genTheoreticalModel
    IntXVals = 1e3*md.voxelsize.x*mgrid[-150:150]
NameError: global name 'mgrid' is not defined
/Users/david/python-microscopy/doc/api/Acquire/Hardware/PYME.Acquire.Hardware.Simulator.rend_im.rst:4: WARNING: autodoc: failed to import module u'PYME.Acquire.Hardware.Simulator.rend_im'; the following exception was raised:
Traceback (most recent call last):
  File "/Users/david/anaconda/lib/python2.7/site-packages/Sphinx-1.3.1-py2.7.egg/sphinx/ext/autodoc.py", line 385, in import_object
    __import__(self.modname)
  File "/Users/david/python-microscopy/PYME/Acquire/Hardware/Simulator/rend_im.py", line 101, in <module>
    genTheoreticalModel(MetaData.TIRFDefault)
  File "/Users/david/python-microscopy/PYME/Acquire/Hardware/Simulator/rend_im.py", line 82, in genTheoreticalModel
    IntXVals = 1e3*md.voxelsize.x*mgrid[-150:150]
NameError: global name 'mgrid' is not defined
/Users/david/python-microscopy/doc/api/Acquire/Hardware/PYME.Acquire.Hardware.Spectrometer.remoteSpectrometer.rst:4: WARNING: autodoc: failed to import module u'PYME.Acquire.Hardware.Spectrometer.remoteSpectrometer'; the following exception was raised:
Traceback (most recent call last):
  File "/Users/david/anaconda/lib/python2.7/site-packages/Sphinx-1.3.1-py2.7.egg/sphinx/ext/autodoc.py", line 385, in import_object
    __import__(self.modname)
  File "/Users/david/python-microscopy/PYME/Acquire/Hardware/Spectrometer/remoteSpectrometer.py", line 27, in <module>
    import com.oceanoptics.omnidriver.api.wrapper.Wrapper
ImportError: No module named com.oceanoptics.omnidriver.api.wrapper.Wrapper
/Users/david/python-microscopy/doc/api/Acquire/Hardware/PYME.Acquire.Hardware.TiLightCrafter.rst:4: WARNING: autodoc: failed to import module u'PYME.Acquire.Hardware.TiLightCrafter'; the following exception was raised:
Traceback (most recent call last):
  File "/Users/david/anaconda/lib/python2.7/site-packages/Sphinx-1.3.1-py2.7.egg/sphinx/ext/autodoc.py", line 385, in import_object
    __import__(self.modname)
  File "/Users/david/python-microscopy/PYME/Acquire/Hardware/TiLightCrafter.py", line 111, in <module>
    class LightCrafter(object):
  File "/Users/david/python-microscopy/PYME/Acquire/Hardware/TiLightCrafter.py", line 112, in LightCrafter
    X, Y = np.mgrid[0:608, 0:684]
TypeError: 'Mock' object has no attribute '__getitem__'
[u"ccdCalibrator(gains=<Mock name='mock.arange()' id='4493747024'>)", u':module: PYME.Acquire.Hardware.ccdCalibrator', u'', u'', u'', u'', u'class for calibrating the ccd', u'', u'usage:', u'- use transmitted light to produce a roughly uniform field', u'- make sure CCD temperature has settled to the the specified set point', u'- adjust intensity and integration time so that camera is not saturated at', u'  the maximum em gain which is going to be calibrated for (220 when using', u'  default options). To give good results the image at max em-gain should', u'  however be bright - ~50% of saturation seems like a good point. Note that', u'  this WILL saturate the display (12 bits as opposed to 16) - use the', u'  histogram display.', u'- instantiate the class on the console - ie:', u'  from PYME.Hardware import ccdCalibrator', u'  ccdCal = ccdCalibrator.ccdCalibrator(scope.pa, scope.cam)', u'', u'', u'.. py:method:: ccdCalibrator.finish()', u'   :module: PYME.Acquire.Hardware.ccdCalibrator', u'', u'   ', u'   ', u'   ', u'   ', u'', u'.. py:method:: ccdCalibrator.tick(caller)', u'   :module: PYME.Acquire.Hardware.ccdCalibrator']:9: ERROR: Unexpected indentation.
/Users/david/python-microscopy/PYME/Acquire/Hardware/ccdCalibrator.py:docstring of PYME.Acquire.Hardware.ccdCalibrator.ccdCalibrator:16: WARNING: Block quote ends without a blank line; unexpected unindent.
/Users/david/python-microscopy/doc/api/Acquire/Hardware/PYME.Acquire.Hardware.thorlabsPiezo.rst:4: WARNING: autodoc: failed to import module u'PYME.Acquire.Hardware.thorlabsPiezo'; the following exception was raised:
Traceback (most recent call last):
  File "/Users/david/anaconda/lib/python2.7/site-packages/Sphinx-1.3.1-py2.7.egg/sphinx/ext/autodoc.py", line 385, in import_object
    __import__(self.modname)
  File "/Users/david/python-microscopy/PYME/Acquire/Hardware/thorlabsPiezo.py", line 24, in <module>
    import win32com.client
ImportError: No module named win32com.client
/Users/david/python-microscopy/doc/api/Acquire/Hardware/PYME.Acquire.Hardware.uc480.uCam480.rst:4: WARNING: autodoc: failed to import module u'PYME.Acquire.Hardware.uc480.uCam480'; the following exception was raised:
Traceback (most recent call last):
  File "/Users/david/anaconda/lib/python2.7/site-packages/Sphinx-1.3.1-py2.7.egg/sphinx/ext/autodoc.py", line 385, in import_object
    __import__(self.modname)
  File "/Users/david/python-microscopy/PYME/Acquire/Hardware/uc480/uCam480.py", line 24, in <module>
    from . import uc480
  File "/Users/david/python-microscopy/PYME/Acquire/Hardware/uc480/uc480.py", line 10, in <module>
    import ctypes.wintypes
  File "/Users/david/anaconda/lib/python2.7/ctypes/wintypes.py", line 23, in <module>
    class VARIANT_BOOL(_SimpleCData):
ValueError: _type_ 'v' not supported
/Users/david/python-microscopy/doc/api/Acquire/Hardware/PYME.Acquire.Hardware.uc480.uc480.rst:4: WARNING: autodoc: failed to import module u'PYME.Acquire.Hardware.uc480.uc480'; the following exception was raised:
Traceback (most recent call last):
  File "/Users/david/anaconda/lib/python2.7/site-packages/Sphinx-1.3.1-py2.7.egg/sphinx/ext/autodoc.py", line 385, in import_object
    __import__(self.modname)
  File "/Users/david/python-microscopy/PYME/Acquire/Hardware/uc480/uc480.py", line 10, in <module>
    import ctypes.wintypes
  File "/Users/david/anaconda/lib/python2.7/ctypes/wintypes.py", line 23, in <module>
    class VARIANT_BOOL(_SimpleCData):
ValueError: _type_ 'v' not supported
/Users/david/python-microscopy/doc/api/Acquire/PYME.Acquire.rst:39: WARNING: toctree contains reference to nonexisting document u'api/Acquire/PYME.Acquire.prevviewer'
/Users/david/python-microscopy/PYME/Acquire/MetaDataHandler.py:docstring of PYME.Acquire.MetaDataHandler:9: ERROR: Unexpected indentation.
/Users/david/python-microscopy/PYME/Acquire/Spooler.py:docstring of PYME.Acquire.Spooler.EventLogger.logEvent:6: WARNING: Explicit markup ends without a blank line; unexpected unindent.
/Users/david/python-microscopy/doc/api/Analysis/DataSources/PYME.Analysis.DataSources.BGSDataSourceX.rst:4: WARNING: autodoc: failed to import module u'PYME.Analysis.DataSources.BGSDataSourceX'; the following exception was raised:
Traceback (most recent call last):
  File "/Users/david/anaconda/lib/python2.7/site-packages/Sphinx-1.3.1-py2.7.egg/sphinx/ext/autodoc.py", line 385, in import_object
    __import__(self.modname)
ImportError: No module named BGSDataSourceX
/Users/david/python-microscopy/doc/api/Analysis/DataSources/PYME.Analysis.DataSources.DcimgDataSource.rst:4: WARNING: autodoc: failed to import module u'PYME.Analysis.DataSources.DcimgDataSource'; the following exception was raised:
Traceback (most recent call last):
  File "/Users/david/anaconda/lib/python2.7/site-packages/Sphinx-1.3.1-py2.7.egg/sphinx/ext/autodoc.py", line 385, in import_object
    __import__(self.modname)
  File "/Users/david/python-microscopy/PYME/Analysis/DataSources/DcimgDataSource.py", line 27, in <module>
    import dcimg
ImportError: No module named dcimg
/Users/david/python-microscopy/doc/api/Analysis/FitFactories/PYME.Analysis.FitFactories.rst:50: WARNING: missing attribute mentioned in :members: or __all__: module PYME.Analysis.FitFactories, attribute AstigGaussFitFR
/Users/david/python-microscopy/doc/api/Analysis/FitFactories/PYME.Analysis.FitFactories.rst:50: WARNING: missing attribute mentioned in :members: or __all__: module PYME.Analysis.FitFactories, attribute DumbellFitR
/Users/david/python-microscopy/doc/api/Analysis/FitFactories/PYME.Analysis.FitFactories.rst:50: WARNING: missing attribute mentioned in :members: or __all__: module PYME.Analysis.FitFactories, attribute Gauss3DFitR
/Users/david/python-microscopy/doc/api/Analysis/FitFactories/PYME.Analysis.FitFactories.rst:50: WARNING: missing attribute mentioned in :members: or __all__: module PYME.Analysis.FitFactories, attribute GaussMultifitLinesR
/Users/david/python-microscopy/doc/api/Analysis/FitFactories/PYME.Analysis.FitFactories.rst:50: WARNING: missing attribute mentioned in :members: or __all__: module PYME.Analysis.FitFactories, attribute GaussMultifitR
/Users/david/python-microscopy/doc/api/Analysis/FitFactories/PYME.Analysis.FitFactories.rst:50: WARNING: missing attribute mentioned in :members: or __all__: module PYME.Analysis.FitFactories, attribute GaussMultifitSR
/Users/david/python-microscopy/doc/api/Analysis/FitFactories/PYME.Analysis.FitFactories.rst:50: WARNING: missing attribute mentioned in :members: or __all__: module PYME.Analysis.FitFactories, attribute InterpFitR
/Users/david/python-microscopy/doc/api/Analysis/FitFactories/PYME.Analysis.FitFactories.rst:50: WARNING: missing attribute mentioned in :members: or __all__: module PYME.Analysis.FitFactories, attribute InterpFitWFR
/Users/david/python-microscopy/doc/api/Analysis/FitFactories/PYME.Analysis.FitFactories.rst:50: WARNING: missing attribute mentioned in :members: or __all__: module PYME.Analysis.FitFactories, attribute LatGaussFitFR
/Users/david/python-microscopy/doc/api/Analysis/FitFactories/PYME.Analysis.FitFactories.rst:50: WARNING: missing attribute mentioned in :members: or __all__: module PYME.Analysis.FitFactories, attribute LatGaussFitlmR
/Users/david/python-microscopy/doc/api/Analysis/FitFactories/PYME.Analysis.FitFactories.rst:50: WARNING: missing attribute mentioned in :members: or __all__: module PYME.Analysis.FitFactories, attribute LatPSFFitR
/Users/david/python-microscopy/doc/api/Analysis/FitFactories/PYME.Analysis.FitFactories.rst:50: WARNING: missing attribute mentioned in :members: or __all__: module PYME.Analysis.FitFactories, attribute PRInterpFitQR
/Users/david/python-microscopy/doc/api/Analysis/FitFactories/PYME.Analysis.FitFactories.rst:50: WARNING: missing attribute mentioned in :members: or __all__: module PYME.Analysis.FitFactories, attribute PRInterpFitR
/Users/david/python-microscopy/doc/api/Analysis/FitFactories/PYME.Analysis.FitFactories.rst:50: WARNING: missing attribute mentioned in :members: or __all__: module PYME.Analysis.FitFactories, attribute SpecGaussFitFR
/Users/david/python-microscopy/doc/api/Analysis/FitFactories/PYME.Analysis.FitFactories.rst:50: WARNING: missing attribute mentioned in :members: or __all__: module PYME.Analysis.FitFactories, attribute SplitterFitFNR
/Users/david/python-microscopy/doc/api/Analysis/FitFactories/PYME.Analysis.FitFactories.rst:50: WARNING: missing attribute mentioned in :members: or __all__: module PYME.Analysis.FitFactories, attribute SplitterFitFusionR
/Users/david/python-microscopy/doc/api/Analysis/FitFactories/PYME.Analysis.FitFactories.rst:50: WARNING: missing attribute mentioned in :members: or __all__: module PYME.Analysis.FitFactories, attribute SplitterFitInterpBNR
/Users/david/python-microscopy/doc/api/Analysis/FitFactories/PYME.Analysis.FitFactories.rst:50: WARNING: missing attribute mentioned in :members: or __all__: module PYME.Analysis.FitFactories, attribute SplitterFitInterpNR
/Users/david/python-microscopy/doc/api/Analysis/FitFactories/PYME.Analysis.FitFactories.rst:50: WARNING: missing attribute mentioned in :members: or __all__: module PYME.Analysis.FitFactories, attribute SplitterMultifitSR
/Users/david/python-microscopy/doc/api/Analysis/FitFactories/PYME.Analysis.FitFactories.rst:50: WARNING: missing attribute mentioned in :members: or __all__: module PYME.Analysis.FitFactories, attribute SplitterObjFindR
/Users/david/python-microscopy/doc/api/Analysis/FitFactories/PYME.Analysis.FitFactories.rst:50: WARNING: missing attribute mentioned in :members: or __all__: module PYME.Analysis.FitFactories, attribute SplitterShiftEstFR
/Users/david/python-microscopy/doc/api/Analysis/FitFactories/PYME.Analysis.FitFactories.AstigGaussFitFR.rst:4: WARNING: autodoc: failed to import module u'PYME.Analysis.FitFactories.AstigGaussFitFR'; the following exception was raised:
Traceback (most recent call last):
  File "/Users/david/anaconda/lib/python2.7/site-packages/Sphinx-1.3.1-py2.7.egg/sphinx/ext/autodoc.py", line 385, in import_object
    __import__(self.modname)
  File "/Users/david/python-microscopy/PYME/Analysis/FitFactories/AstigGaussFitFR.py", line 29, in <module>
    from PYME.Analysis._fithelpers import FitModelWeighted, FitModelWeightedJac
  File "/Users/david/python-microscopy/PYME/Analysis/_fithelpers.py", line 25, in <module>
    import scipy.optimize as optimize
ImportError: No module named optimize
/Users/david/python-microscopy/doc/api/Analysis/FitFactories/PYME.Analysis.FitFactories.DumbellFitR.rst:4: WARNING: autodoc: failed to import module u'PYME.Analysis.FitFactories.DumbellFitR'; the following exception was raised:
Traceback (most recent call last):
  File "/Users/david/anaconda/lib/python2.7/site-packages/Sphinx-1.3.1-py2.7.egg/sphinx/ext/autodoc.py", line 385, in import_object
    __import__(self.modname)
  File "/Users/david/python-microscopy/PYME/Analysis/FitFactories/DumbellFitR.py", line 28, in <module>
    from PYME.Analysis._fithelpers import FitModelWeighted, FitModelWeightedJac
  File "/Users/david/python-microscopy/PYME/Analysis/_fithelpers.py", line 25, in <module>
    import scipy.optimize as optimize
ImportError: No module named optimize
/Users/david/python-microscopy/doc/api/Analysis/FitFactories/PYME.Analysis.FitFactories.Gauss3DFitR.rst:4: WARNING: autodoc: failed to import module u'PYME.Analysis.FitFactories.Gauss3DFitR'; the following exception was raised:
Traceback (most recent call last):
  File "/Users/david/anaconda/lib/python2.7/site-packages/Sphinx-1.3.1-py2.7.egg/sphinx/ext/autodoc.py", line 385, in import_object
    __import__(self.modname)
  File "/Users/david/python-microscopy/PYME/Analysis/FitFactories/Gauss3DFitR.py", line 28, in <module>
    from PYME.Analysis._fithelpers import *
  File "/Users/david/python-microscopy/PYME/Analysis/_fithelpers.py", line 25, in <module>
    import scipy.optimize as optimize
ImportError: No module named optimize
/Users/david/python-microscopy/doc/api/Analysis/FitFactories/PYME.Analysis.FitFactories.GaussMultifitLinesR.rst:4: WARNING: autodoc: failed to import module u'PYME.Analysis.FitFactories.GaussMultifitLinesR'; the following exception was raised:
Traceback (most recent call last):
  File "/Users/david/anaconda/lib/python2.7/site-packages/Sphinx-1.3.1-py2.7.egg/sphinx/ext/autodoc.py", line 385, in import_object
    __import__(self.modname)
  File "/Users/david/python-microscopy/PYME/Analysis/FitFactories/GaussMultifitLinesR.py", line 30, in <module>
    from PYME.Analysis._fithelpers import *
  File "/Users/david/python-microscopy/PYME/Analysis/_fithelpers.py", line 25, in <module>
    import scipy.optimize as optimize
ImportError: No module named optimize
/Users/david/python-microscopy/doc/api/Analysis/FitFactories/PYME.Analysis.FitFactories.GaussMultifitR.rst:4: WARNING: autodoc: failed to import module u'PYME.Analysis.FitFactories.GaussMultifitR'; the following exception was raised:
Traceback (most recent call last):
  File "/Users/david/anaconda/lib/python2.7/site-packages/Sphinx-1.3.1-py2.7.egg/sphinx/ext/autodoc.py", line 385, in import_object
    __import__(self.modname)
  File "/Users/david/python-microscopy/PYME/Analysis/FitFactories/GaussMultifitR.py", line 28, in <module>
    from PYME.Analysis._fithelpers import *
  File "/Users/david/python-microscopy/PYME/Analysis/_fithelpers.py", line 25, in <module>
    import scipy.optimize as optimize
ImportError: No module named optimize
/Users/david/python-microscopy/doc/api/Analysis/FitFactories/PYME.Analysis.FitFactories.GaussMultifitSR.rst:4: WARNING: autodoc: failed to import module u'PYME.Analysis.FitFactories.GaussMultifitSR'; the following exception was raised:
Traceback (most recent call last):
  File "/Users/david/anaconda/lib/python2.7/site-packages/Sphinx-1.3.1-py2.7.egg/sphinx/ext/autodoc.py", line 385, in import_object
    __import__(self.modname)
  File "/Users/david/python-microscopy/PYME/Analysis/FitFactories/GaussMultifitSR.py", line 30, in <module>
    from PYME.Analysis._fithelpers import *
  File "/Users/david/python-microscopy/PYME/Analysis/_fithelpers.py", line 25, in <module>
    import scipy.optimize as optimize
ImportError: No module named optimize
/Users/david/python-microscopy/doc/api/Analysis/FitFactories/PYME.Analysis.FitFactories.InterpFitR.rst:4: WARNING: autodoc: failed to import module u'PYME.Analysis.FitFactories.InterpFitR'; the following exception was raised:
Traceback (most recent call last):
  File "/Users/david/anaconda/lib/python2.7/site-packages/Sphinx-1.3.1-py2.7.egg/sphinx/ext/autodoc.py", line 385, in import_object
    __import__(self.modname)
  File "/Users/david/python-microscopy/PYME/Analysis/FitFactories/InterpFitR.py", line 34, in <module>
    from PYME.Analysis._fithelpers import FitModelWeighted_, FitModelWeighted, FitModelWeightedJac
  File "/Users/david/python-microscopy/PYME/Analysis/_fithelpers.py", line 25, in <module>
    import scipy.optimize as optimize
ImportError: No module named optimize
/Users/david/python-microscopy/doc/api/Analysis/FitFactories/PYME.Analysis.FitFactories.InterpFitWFR.rst:4: WARNING: autodoc: failed to import module u'PYME.Analysis.FitFactories.InterpFitWFR'; the following exception was raised:
Traceback (most recent call last):
  File "/Users/david/anaconda/lib/python2.7/site-packages/Sphinx-1.3.1-py2.7.egg/sphinx/ext/autodoc.py", line 385, in import_object
    __import__(self.modname)
  File "/Users/david/python-microscopy/PYME/Analysis/FitFactories/InterpFitWFR.py", line 34, in <module>
    from .InterpFitR import PSFFitFactory, PSFFitResultR, fresultdtype, genFitImage, getDataErrors
  File "/Users/david/python-microscopy/PYME/Analysis/FitFactories/InterpFitR.py", line 34, in <module>
    from PYME.Analysis._fithelpers import FitModelWeighted_, FitModelWeighted, FitModelWeightedJac
  File "/Users/david/python-microscopy/PYME/Analysis/_fithelpers.py", line 25, in <module>
    import scipy.optimize as optimize
ImportError: No module named optimize
/Users/david/python-microscopy/doc/api/Analysis/FitFactories/PYME.Analysis.FitFactories.Interpolators.rst:19: WARNING: missing attribute mentioned in :members: or __all__: module PYME.Analysis.FitFactories.Interpolators, attribute baseInterpolator
/Users/david/python-microscopy/doc/api/Analysis/FitFactories/PYME.Analysis.FitFactories.Interpolators.rst:19: WARNING: missing attribute mentioned in :members: or __all__: module PYME.Analysis.FitFactories.Interpolators, attribute CSInterpolator
/Users/david/python-microscopy/doc/api/Analysis/FitFactories/PYME.Analysis.FitFactories.Interpolators.rst:19: WARNING: missing attribute mentioned in :members: or __all__: module PYME.Analysis.FitFactories.Interpolators, attribute CubeSInterpolatorP
/Users/david/python-microscopy/doc/api/Analysis/FitFactories/PYME.Analysis.FitFactories.Interpolators.rst:19: WARNING: missing attribute mentioned in :members: or __all__: module PYME.Analysis.FitFactories.Interpolators, attribute CubicSplineInterpolator
/Users/david/python-microscopy/doc/api/Analysis/FitFactories/PYME.Analysis.FitFactories.Interpolators.rst:19: WARNING: missing attribute mentioned in :members: or __all__: module PYME.Analysis.FitFactories.Interpolators, attribute LinearInterpolator
/Users/david/python-microscopy/doc/api/Analysis/FitFactories/PYME.Analysis.FitFactories.Interpolators.rst:19: WARNING: missing attribute mentioned in :members: or __all__: module PYME.Analysis.FitFactories.Interpolators, attribute LinearPInterpolatorP
/Users/david/python-microscopy/doc/api/Analysis/FitFactories/PYME.Analysis.FitFactories.LatGaussFitFR.rst:4: WARNING: autodoc: failed to import module u'PYME.Analysis.FitFactories.LatGaussFitFR'; the following exception was raised:
Traceback (most recent call last):
  File "/Users/david/anaconda/lib/python2.7/site-packages/Sphinx-1.3.1-py2.7.egg/sphinx/ext/autodoc.py", line 385, in import_object
    __import__(self.modname)
  File "/Users/david/python-microscopy/PYME/Analysis/FitFactories/LatGaussFitFR.py", line 29, in <module>
    from PYME.Analysis._fithelpers import FitModelWeighted, FitModelWeightedJac
  File "/Users/david/python-microscopy/PYME/Analysis/_fithelpers.py", line 25, in <module>
    import scipy.optimize as optimize
ImportError: No module named optimize
/Users/david/python-microscopy/doc/api/Analysis/FitFactories/PYME.Analysis.FitFactories.LatGaussFitlmR.rst:4: WARNING: autodoc: failed to import module u'PYME.Analysis.FitFactories.LatGaussFitlmR'; the following exception was raised:
Traceback (most recent call last):
  File "/Users/david/anaconda/lib/python2.7/site-packages/Sphinx-1.3.1-py2.7.egg/sphinx/ext/autodoc.py", line 385, in import_object
    __import__(self.modname)
  File "/Users/david/python-microscopy/PYME/Analysis/FitFactories/LatGaussFitlmR.py", line 33, in <module>
    from PYME.Analysis.lev_gfit.levmar_gfit import *
ImportError: No module named levmar_gfit
/Users/david/python-microscopy/doc/api/Analysis/FitFactories/PYME.Analysis.FitFactories.LatPSFFitR.rst:4: WARNING: autodoc: failed to import module u'PYME.Analysis.FitFactories.LatPSFFitR'; the following exception was raised:
Traceback (most recent call last):
  File "/Users/david/anaconda/lib/python2.7/site-packages/Sphinx-1.3.1-py2.7.egg/sphinx/ext/autodoc.py", line 385, in import_object
    __import__(self.modname)
  File "/Users/david/python-microscopy/PYME/Analysis/FitFactories/LatPSFFitR.py", line 27, in <module>
    from PYME.Analysis._fithelpers import FitModelWeighted
  File "/Users/david/python-microscopy/PYME/Analysis/_fithelpers.py", line 25, in <module>
    import scipy.optimize as optimize
ImportError: No module named optimize
/Users/david/python-microscopy/doc/api/Analysis/FitFactories/PYME.Analysis.FitFactories.PRInterpFitQR.rst:4: WARNING: autodoc: failed to import module u'PYME.Analysis.FitFactories.PRInterpFitQR'; the following exception was raised:
Traceback (most recent call last):
  File "/Users/david/anaconda/lib/python2.7/site-packages/Sphinx-1.3.1-py2.7.egg/sphinx/ext/autodoc.py", line 385, in import_object
    __import__(self.modname)
  File "/Users/david/python-microscopy/PYME/Analysis/FitFactories/PRInterpFitQR.py", line 27, in <module>
    from . import InterpFitR
  File "/Users/david/python-microscopy/PYME/Analysis/FitFactories/InterpFitR.py", line 34, in <module>
    from PYME.Analysis._fithelpers import FitModelWeighted_, FitModelWeighted, FitModelWeightedJac
  File "/Users/david/python-microscopy/PYME/Analysis/_fithelpers.py", line 25, in <module>
    import scipy.optimize as optimize
ImportError: No module named optimize
/Users/david/python-microscopy/doc/api/Analysis/FitFactories/PYME.Analysis.FitFactories.PRInterpFitR.rst:4: WARNING: autodoc: failed to import module u'PYME.Analysis.FitFactories.PRInterpFitR'; the following exception was raised:
Traceback (most recent call last):
  File "/Users/david/anaconda/lib/python2.7/site-packages/Sphinx-1.3.1-py2.7.egg/sphinx/ext/autodoc.py", line 385, in import_object
    __import__(self.modname)
  File "/Users/david/python-microscopy/PYME/Analysis/FitFactories/PRInterpFitR.py", line 27, in <module>
    from . import InterpFitR
  File "/Users/david/python-microscopy/PYME/Analysis/FitFactories/InterpFitR.py", line 34, in <module>
    from PYME.Analysis._fithelpers import FitModelWeighted_, FitModelWeighted, FitModelWeightedJac
  File "/Users/david/python-microscopy/PYME/Analysis/_fithelpers.py", line 25, in <module>
    import scipy.optimize as optimize
ImportError: No module named optimize
/Users/david/python-microscopy/doc/api/Analysis/FitFactories/PYME.Analysis.FitFactories.SpecGaussFitFR.rst:4: WARNING: autodoc: failed to import module u'PYME.Analysis.FitFactories.SpecGaussFitFR'; the following exception was raised:
Traceback (most recent call last):
  File "/Users/david/anaconda/lib/python2.7/site-packages/Sphinx-1.3.1-py2.7.egg/sphinx/ext/autodoc.py", line 385, in import_object
    __import__(self.modname)
  File "/Users/david/python-microscopy/PYME/Analysis/FitFactories/SpecGaussFitFR.py", line 35, in <module>
    from PYME.Analysis._fithelpers import *
  File "/Users/david/python-microscopy/PYME/Analysis/_fithelpers.py", line 25, in <module>
    import scipy.optimize as optimize
ImportError: No module named optimize
/Users/david/python-microscopy/doc/api/Analysis/FitFactories/PYME.Analysis.FitFactories.SplitterFitFNR.rst:4: WARNING: autodoc: failed to import module u'PYME.Analysis.FitFactories.SplitterFitFNR'; the following exception was raised:
Traceback (most recent call last):
  File "/Users/david/anaconda/lib/python2.7/site-packages/Sphinx-1.3.1-py2.7.egg/sphinx/ext/autodoc.py", line 385, in import_object
    __import__(self.modname)
  File "/Users/david/python-microscopy/PYME/Analysis/FitFactories/SplitterFitFNR.py", line 33, in <module>
    from PYME.Analysis._fithelpers import *
  File "/Users/david/python-microscopy/PYME/Analysis/_fithelpers.py", line 25, in <module>
    import scipy.optimize as optimize
ImportError: No module named optimize
/Users/david/python-microscopy/doc/api/Analysis/FitFactories/PYME.Analysis.FitFactories.SplitterFitFusionR.rst:4: WARNING: autodoc: failed to import module u'PYME.Analysis.FitFactories.SplitterFitFusionR'; the following exception was raised:
Traceback (most recent call last):
  File "/Users/david/anaconda/lib/python2.7/site-packages/Sphinx-1.3.1-py2.7.egg/sphinx/ext/autodoc.py", line 385, in import_object
    __import__(self.modname)
  File "/Users/david/python-microscopy/PYME/Analysis/FitFactories/SplitterFitFusionR.py", line 33, in <module>
    from PYME.Analysis._fithelpers import *
  File "/Users/david/python-microscopy/PYME/Analysis/_fithelpers.py", line 25, in <module>
    import scipy.optimize as optimize
ImportError: No module named optimize
/Users/david/python-microscopy/doc/api/Analysis/FitFactories/PYME.Analysis.FitFactories.SplitterFitInterpBNR.rst:4: WARNING: autodoc: failed to import module u'PYME.Analysis.FitFactories.SplitterFitInterpBNR'; the following exception was raised:
Traceback (most recent call last):
  File "/Users/david/anaconda/lib/python2.7/site-packages/Sphinx-1.3.1-py2.7.egg/sphinx/ext/autodoc.py", line 385, in import_object
    __import__(self.modname)
  File "/Users/david/python-microscopy/PYME/Analysis/FitFactories/SplitterFitInterpBNR.py", line 32, in <module>
    from . import InterpFitR
  File "/Users/david/python-microscopy/PYME/Analysis/FitFactories/InterpFitR.py", line 34, in <module>
    from PYME.Analysis._fithelpers import FitModelWeighted_, FitModelWeighted, FitModelWeightedJac
  File "/Users/david/python-microscopy/PYME/Analysis/_fithelpers.py", line 25, in <module>
    import scipy.optimize as optimize
ImportError: No module named optimize
/Users/david/python-microscopy/doc/api/Analysis/FitFactories/PYME.Analysis.FitFactories.SplitterFitInterpNR.rst:4: WARNING: autodoc: failed to import module u'PYME.Analysis.FitFactories.SplitterFitInterpNR'; the following exception was raised:
Traceback (most recent call last):
  File "/Users/david/anaconda/lib/python2.7/site-packages/Sphinx-1.3.1-py2.7.egg/sphinx/ext/autodoc.py", line 385, in import_object
    __import__(self.modname)
  File "/Users/david/python-microscopy/PYME/Analysis/FitFactories/SplitterFitInterpNR.py", line 32, in <module>
    from . import InterpFitR
  File "/Users/david/python-microscopy/PYME/Analysis/FitFactories/InterpFitR.py", line 34, in <module>
    from PYME.Analysis._fithelpers import FitModelWeighted_, FitModelWeighted, FitModelWeightedJac
  File "/Users/david/python-microscopy/PYME/Analysis/_fithelpers.py", line 25, in <module>
    import scipy.optimize as optimize
ImportError: No module named optimize
/Users/david/python-microscopy/doc/api/Analysis/FitFactories/PYME.Analysis.FitFactories.SplitterMultifitSR.rst:4: WARNING: autodoc: failed to import module u'PYME.Analysis.FitFactories.SplitterMultifitSR'; the following exception was raised:
Traceback (most recent call last):
  File "/Users/david/anaconda/lib/python2.7/site-packages/Sphinx-1.3.1-py2.7.egg/sphinx/ext/autodoc.py", line 385, in import_object
    __import__(self.modname)
  File "/Users/david/python-microscopy/PYME/Analysis/FitFactories/SplitterMultifitSR.py", line 36, in <module>
    from PYME.Analysis._fithelpers import *
  File "/Users/david/python-microscopy/PYME/Analysis/_fithelpers.py", line 25, in <module>
    import scipy.optimize as optimize
ImportError: No module named optimize
/Users/david/python-microscopy/doc/api/Analysis/FitFactories/PYME.Analysis.FitFactories.SplitterObjFindR.rst:4: WARNING: autodoc: failed to import module u'PYME.Analysis.FitFactories.SplitterObjFindR'; the following exception was raised:
Traceback (most recent call last):
  File "/Users/david/anaconda/lib/python2.7/site-packages/Sphinx-1.3.1-py2.7.egg/sphinx/ext/autodoc.py", line 385, in import_object
    __import__(self.modname)
  File "/Users/david/python-microscopy/PYME/Analysis/FitFactories/SplitterObjFindR.py", line 32, in <module>
    import PYME.Analysis.twoColour as twoColour
  File "/Users/david/python-microscopy/PYME/Analysis/twoColour.py", line 27, in <module>
    from PYME.Analysis import ofind
  File "/Users/david/python-microscopy/PYME/Analysis/ofind.py", line 56, in <module>
    weightsLowpass = calc_gauss_weights(filtRadLowpass)
  File "/Users/david/python-microscopy/PYME/Analysis/ofind.py", line 39, in calc_gauss_weights
    weights[lw] = 1.0
TypeError: 'Mock' object does not support item assignment
/Users/david/python-microscopy/doc/api/Analysis/FitFactories/PYME.Analysis.FitFactories.SplitterShiftEstFR.rst:4: WARNING: autodoc: failed to import module u'PYME.Analysis.FitFactories.SplitterShiftEstFR'; the following exception was raised:
Traceback (most recent call last):
  File "/Users/david/anaconda/lib/python2.7/site-packages/Sphinx-1.3.1-py2.7.egg/sphinx/ext/autodoc.py", line 385, in import_object
    __import__(self.modname)
  File "/Users/david/python-microscopy/PYME/Analysis/FitFactories/SplitterShiftEstFR.py", line 38, in <module>
    from PYME.Analysis._fithelpers import *
  File "/Users/david/python-microscopy/PYME/Analysis/_fithelpers.py", line 25, in <module>
    import scipy.optimize as optimize
ImportError: No module named optimize
/Users/david/python-microscopy/doc/api/Analysis/FitFactories/PYME.Analysis.FitFactories.zEstimators.rst:16: WARNING: missing attribute mentioned in :members: or __all__: module PYME.Analysis.FitFactories.zEstimators, attribute astigEstimator
/Users/david/python-microscopy/doc/api/Analysis/FitFactories/PYME.Analysis.FitFactories.zEstimators.rst:16: WARNING: missing attribute mentioned in :members: or __all__: module PYME.Analysis.FitFactories.zEstimators, attribute biplaneEstimator
/Users/david/python-microscopy/doc/api/Analysis/FitFactories/PYME.Analysis.FitFactories.zEstimators.rst:16: WARNING: missing attribute mentioned in :members: or __all__: module PYME.Analysis.FitFactories.zEstimators, attribute priEstimator
/Users/david/python-microscopy/doc/api/Analysis/LMVis/PYME.Analysis.LMVis.Extras.pointSetGeneration.rst:4: WARNING: autodoc: failed to import module u'PYME.Analysis.LMVis.Extras.pointSetGeneration'; the module executes module level statement and it might call sys.exit().
/Users/david/python-microscopy/doc/api/Analysis/LMVis/PYME.Analysis.LMVis.VisGUI.rst:4: WARNING: autodoc: failed to import module u'PYME.Analysis.LMVis.VisGUI'; the following exception was raised:
Traceback (most recent call last):
  File "/Users/david/anaconda/lib/python2.7/site-packages/Sphinx-1.3.1-py2.7.egg/sphinx/ext/autodoc.py", line 385, in import_object
    __import__(self.modname)
  File "/Users/david/python-microscopy/PYME/Analysis/LMVis/VisGUI.py", line 32, in <module>
    from PYME.Analysis.LMVis import gl_render
  File "/Users/david/python-microscopy/PYME/Analysis/LMVis/gl_render.py", line 30, in <module>
    from OpenGL.GL import *
  File "/Users/david/anaconda/lib/python2.7/site-packages/OpenGL/GL/__init__.py", line 3, in <module>
    from OpenGL.GL.VERSION.GL_1_1 import *
  File "/Users/david/anaconda/lib/python2.7/site-packages/OpenGL/GL/VERSION/GL_1_1.py", line 10, in <module>
    from OpenGL import platform, constants, constant, arrays
  File "/Users/david/anaconda/lib/python2.7/site-packages/OpenGL/arrays/__init__.py", line 22, in <module>
    formathandler.FormatHandler.loadAll()
  File "/Users/david/anaconda/lib/python2.7/site-packages/OpenGL/arrays/formathandler.py", line 28, in loadAll
    cls.loadPlugin( entrypoint )
  File "/Users/david/anaconda/lib/python2.7/site-packages/OpenGL/arrays/formathandler.py", line 35, in loadPlugin
    plugin_class = entrypoint.load()
  File "/Users/david/anaconda/lib/python2.7/site-packages/OpenGL/plugins.py", line 14, in load
    return importByName( self.import_path )
  File "/Users/david/anaconda/lib/python2.7/site-packages/OpenGL/plugins.py", line 28, in importByName
    module = __import__( ".".join(moduleName), {}, {}, moduleName)
  File "/Users/david/anaconda/lib/python2.7/site-packages/OpenGL/arrays/numpymodule.py", line 209, in <module>
    lookupDtype(USHORT_TYPE): constants.GL_UNSIGNED_SHORT,
NameError: name 'USHORT_TYPE' is not defined
/Users/david/python-microscopy/doc/api/Analysis/LMVis/PYME.Analysis.LMVis.gen3DTriangs.rst:4: WARNING: autodoc: failed to import module u'PYME.Analysis.LMVis.gen3DTriangs'; the following exception was raised:
Traceback (most recent call last):
  File "/Users/david/anaconda/lib/python2.7/site-packages/Sphinx-1.3.1-py2.7.egg/sphinx/ext/autodoc.py", line 385, in import_object
    __import__(self.modname)
  File "/Users/david/python-microscopy/PYME/Analysis/LMVis/gen3DTriangs.py", line 74, in <module>
    def gen3DTriangs(x,y,z, sizeCutoff=inf, internalCull=True, pcut=inf):
NameError: name 'inf' is not defined
/Users/david/python-microscopy/doc/api/Analysis/LMVis/PYME.Analysis.LMVis.gl_render.rst:4: WARNING: autodoc: failed to import module u'PYME.Analysis.LMVis.gl_render'; the following exception was raised:
Traceback (most recent call last):
  File "/Users/david/anaconda/lib/python2.7/site-packages/Sphinx-1.3.1-py2.7.egg/sphinx/ext/autodoc.py", line 385, in import_object
    __import__(self.modname)
  File "/Users/david/python-microscopy/PYME/Analysis/LMVis/gl_render.py", line 30, in <module>
    from OpenGL.GL import *
  File "/Users/david/anaconda/lib/python2.7/site-packages/OpenGL/GL/__init__.py", line 3, in <module>
    from OpenGL.GL.VERSION.GL_1_1 import *
  File "/Users/david/anaconda/lib/python2.7/site-packages/OpenGL/GL/VERSION/GL_1_1.py", line 10, in <module>
    from OpenGL import platform, constants, constant, arrays
  File "/Users/david/anaconda/lib/python2.7/site-packages/OpenGL/arrays/__init__.py", line 22, in <module>
    formathandler.FormatHandler.loadAll()
  File "/Users/david/anaconda/lib/python2.7/site-packages/OpenGL/arrays/formathandler.py", line 28, in loadAll
    cls.loadPlugin( entrypoint )
  File "/Users/david/anaconda/lib/python2.7/site-packages/OpenGL/arrays/formathandler.py", line 35, in loadPlugin
    plugin_class = entrypoint.load()
  File "/Users/david/anaconda/lib/python2.7/site-packages/OpenGL/plugins.py", line 14, in load
    return importByName( self.import_path )
  File "/Users/david/anaconda/lib/python2.7/site-packages/OpenGL/plugins.py", line 28, in importByName
    module = __import__( ".".join(moduleName), {}, {}, moduleName)
  File "/Users/david/anaconda/lib/python2.7/site-packages/OpenGL/arrays/numpymodule.py", line 209, in <module>
    lookupDtype(USHORT_TYPE): constants.GL_UNSIGNED_SHORT,
NameError: name 'USHORT_TYPE' is not defined
/Users/david/python-microscopy/doc/api/Analysis/LMVis/PYME.Analysis.LMVis.gl_render3D.rst:4: WARNING: autodoc: failed to import module u'PYME.Analysis.LMVis.gl_render3D'; the following exception was raised:
Traceback (most recent call last):
  File "/Users/david/anaconda/lib/python2.7/site-packages/Sphinx-1.3.1-py2.7.egg/sphinx/ext/autodoc.py", line 385, in import_object
    __import__(self.modname)
  File "/Users/david/python-microscopy/PYME/Analysis/LMVis/gl_render3D.py", line 29, in <module>
    from OpenGL.GL import *
  File "/Users/david/anaconda/lib/python2.7/site-packages/OpenGL/GL/__init__.py", line 3, in <module>
    from OpenGL.GL.VERSION.GL_1_1 import *
  File "/Users/david/anaconda/lib/python2.7/site-packages/OpenGL/GL/VERSION/GL_1_1.py", line 10, in <module>
    from OpenGL import platform, constants, constant, arrays
  File "/Users/david/anaconda/lib/python2.7/site-packages/OpenGL/arrays/__init__.py", line 22, in <module>
    formathandler.FormatHandler.loadAll()
  File "/Users/david/anaconda/lib/python2.7/site-packages/OpenGL/arrays/formathandler.py", line 28, in loadAll
    cls.loadPlugin( entrypoint )
  File "/Users/david/anaconda/lib/python2.7/site-packages/OpenGL/arrays/formathandler.py", line 35, in loadPlugin
    plugin_class = entrypoint.load()
  File "/Users/david/anaconda/lib/python2.7/site-packages/OpenGL/plugins.py", line 14, in load
    return importByName( self.import_path )
  File "/Users/david/anaconda/lib/python2.7/site-packages/OpenGL/plugins.py", line 28, in importByName
    module = __import__( ".".join(moduleName), {}, {}, moduleName)
  File "/Users/david/anaconda/lib/python2.7/site-packages/OpenGL/arrays/numpymodule.py", line 209, in <module>
    lookupDtype(USHORT_TYPE): constants.GL_UNSIGNED_SHORT,
NameError: name 'USHORT_TYPE' is not defined
/Users/david/python-microscopy/doc/api/Analysis/LMVis/PYME.Analysis.LMVis.objectMeasure.rst:4: WARNING: autodoc: failed to import module u'PYME.Analysis.LMVis.objectMeasure'; the following exception was raised:
Traceback (most recent call last):
  File "/Users/david/anaconda/lib/python2.7/site-packages/Sphinx-1.3.1-py2.7.egg/sphinx/ext/autodoc.py", line 385, in import_object
    __import__(self.modname)
  File "/Users/david/python-microscopy/PYME/Analysis/LMVis/objectMeasure.py", line 26, in <module>
    import gen3DTriangs
  File "/Users/david/python-microscopy/PYME/Analysis/LMVis/gen3DTriangs.py", line 74, in <module>
    def gen3DTriangs(x,y,z, sizeCutoff=inf, internalCull=True, pcut=inf):
NameError: name 'inf' is not defined
/Users/david/python-microscopy/doc/api/Analysis/LMVis/PYME.Analysis.LMVis.pipeline.rst:4: WARNING: autodoc: failed to import module u'PYME.Analysis.LMVis.pipeline'; the following exception was raised:
Traceback (most recent call last):
  File "/Users/david/anaconda/lib/python2.7/site-packages/Sphinx-1.3.1-py2.7.egg/sphinx/ext/autodoc.py", line 385, in import_object
    __import__(self.modname)
  File "/Users/david/python-microscopy/PYME/Analysis/LMVis/pipeline.py", line 27, in <module>
    from PYME.Analysis.LMVis import renderers
  File "/Users/david/python-microscopy/PYME/Analysis/LMVis/renderers.py", line 33, in <module>
    from PYME.Analysis.QuadTree import QTrend
  File "/Users/david/python-microscopy/PYME/Analysis/QuadTree/__init__.py", line 25, in <module>
    from QTrend import *
  File "/Users/david/python-microscopy/PYME/Analysis/QuadTree/QTrend.py", line 28, in <module>
    def rendQT(ax, qt, maxDepth=-1, cmap=cm.hot, maxIsc = 1):
NameError: name 'cm' is not defined
/Users/david/python-microscopy/doc/api/Analysis/LMVis/PYME.Analysis.LMVis.progGraphC.rst:4: WARNING: autodoc: failed to import module u'PYME.Analysis.LMVis.progGraphC'; the following exception was raised:
Traceback (most recent call last):
  File "/Users/david/anaconda/lib/python2.7/site-packages/Sphinx-1.3.1-py2.7.egg/sphinx/ext/autodoc.py", line 385, in import_object
    __import__(self.modname)
  File "/Users/david/python-microscopy/PYME/Analysis/LMVis/progGraphC.py", line 26, in <module>
    from enthought.chaco.api import HPlotContainer, create_line_plot
ImportError: No module named enthought.chaco.api
/Users/david/python-microscopy/doc/api/Analysis/LMVis/PYME.Analysis.LMVis.progGraphVV.rst:4: WARNING: autodoc: failed to import module u'PYME.Analysis.LMVis.progGraphVV'; the following exception was raised:
Traceback (most recent call last):
  File "/Users/david/anaconda/lib/python2.7/site-packages/Sphinx-1.3.1-py2.7.egg/sphinx/ext/autodoc.py", line 385, in import_object
    __import__(self.modname)
  File "/Users/david/python-microscopy/PYME/Analysis/LMVis/progGraphVV.py", line 25, in <module>
    import visvis as vv
ImportError: No module named visvis
/Users/david/python-microscopy/doc/api/Analysis/LMVis/PYME.Analysis.LMVis.renderers.rst:4: WARNING: autodoc: failed to import module u'PYME.Analysis.LMVis.renderers'; the following exception was raised:
Traceback (most recent call last):
  File "/Users/david/anaconda/lib/python2.7/site-packages/Sphinx-1.3.1-py2.7.egg/sphinx/ext/autodoc.py", line 385, in import_object
    __import__(self.modname)
  File "/Users/david/python-microscopy/PYME/Analysis/LMVis/renderers.py", line 33, in <module>
    from PYME.Analysis.QuadTree import QTrend
  File "/Users/david/python-microscopy/PYME/Analysis/QuadTree/__init__.py", line 25, in <module>
    from QTrend import *
  File "/Users/david/python-microscopy/PYME/Analysis/QuadTree/QTrend.py", line 28, in <module>
    def rendQT(ax, qt, maxDepth=-1, cmap=cm.hot, maxIsc = 1):
NameError: name 'cm' is not defined
/Users/david/python-microscopy/doc/api/Analysis/Modules/PYME.Analysis.Modules.bakeshop.rst:4: WARNING: autodoc: failed to import module u'PYME.Analysis.Modules.bakeshop'; the module executes module level statement and it might call sys.exit().
/Users/david/python-microscopy/doc/api/Analysis/Modules/PYME.Analysis.Modules.base.rst:4: WARNING: autodoc: failed to import module u'PYME.Analysis.Modules.base'; the module executes module level statement and it might call sys.exit().
/Users/david/python-microscopy/doc/api/Analysis/Modules/PYME.Analysis.Modules.batchProcess.rst:4: WARNING: autodoc: failed to import module u'PYME.Analysis.Modules.batchProcess'; the module executes module level statement and it might call sys.exit().
/Users/david/python-microscopy/doc/api/Analysis/Modules/PYME.Analysis.Modules.filters.rst:4: WARNING: autodoc: failed to import module u'PYME.Analysis.Modules.filters'; the module executes module level statement and it might call sys.exit().
/Users/david/python-microscopy/doc/api/Analysis/Modules/PYME.Analysis.Modules.measurement.rst:4: WARNING: autodoc: failed to import module u'PYME.Analysis.Modules.measurement'; the module executes module level statement and it might call sys.exit().
/Users/david/python-microscopy/doc/api/Analysis/Modules/PYME.Analysis.Modules.modules.rst:4: WARNING: autodoc: failed to import module u'PYME.Analysis.Modules.modules'; the module executes module level statement and it might call sys.exit().
/Users/david/python-microscopy/doc/api/Analysis/Modules/PYME.Analysis.Modules.processing.rst:4: WARNING: autodoc: failed to import module u'PYME.Analysis.Modules.processing'; the module executes module level statement and it might call sys.exit().
/Users/david/python-microscopy/doc/api/Analysis/Modules/PYME.Analysis.Modules.recipeGui.rst:4: WARNING: autodoc: failed to import module u'PYME.Analysis.Modules.recipeGui'; the module executes module level statement and it might call sys.exit().
/Users/david/python-microscopy/doc/api/Analysis/Modules/PYME.Analysis.Modules.runRecipe.rst:4: WARNING: autodoc: failed to import module u'PYME.Analysis.Modules.runRecipe'; the module executes module level statement and it might call sys.exit().
/Users/david/python-microscopy/doc/api/Analysis/Modules/PYME.Analysis.Modules.skfilters.rst:4: WARNING: autodoc: failed to import module u'PYME.Analysis.Modules.skfilters'; the module executes module level statement and it might call sys.exit().
/Users/david/python-microscopy/doc/api/Analysis/Modules/PYME.Analysis.Modules.tracking.rst:4: WARNING: autodoc: failed to import module u'PYME.Analysis.Modules.tracking'; the module executes module level statement and it might call sys.exit().
/Users/david/python-microscopy/doc/api/Analysis/PYME.Analysis.Auto.auto_drift_render.rst:4: WARNING: autodoc: failed to import module u'PYME.Analysis.Auto.auto_drift_render'; the following exception was raised:
Traceback (most recent call last):
  File "/Users/david/anaconda/lib/python2.7/site-packages/Sphinx-1.3.1-py2.7.egg/sphinx/ext/autodoc.py", line 385, in import_object
    __import__(self.modname)
  File "/Users/david/python-microscopy/PYME/Analysis/Auto/auto_drift_render.py", line 8, in <module>
    from PYME.Analysis.LMVis.pipeline import Pipeline
  File "/Users/david/python-microscopy/PYME/Analysis/LMVis/pipeline.py", line 27, in <module>
    from PYME.Analysis.LMVis import renderers
  File "/Users/david/python-microscopy/PYME/Analysis/LMVis/renderers.py", line 33, in <module>
    from PYME.Analysis.QuadTree import QTrend
  File "/Users/david/python-microscopy/PYME/Analysis/QuadTree/__init__.py", line 25, in <module>
    from QTrend import *
  File "/Users/david/python-microscopy/PYME/Analysis/QuadTree/QTrend.py", line 28, in <module>
    def rendQT(ax, qt, maxDepth=-1, cmap=cm.hot, maxIsc = 1):
NameError: name 'cm' is not defined
/Users/david/python-microscopy/doc/api/Analysis/PYME.Analysis.Auto.auto_photophysics.rst:4: WARNING: autodoc: failed to import module u'PYME.Analysis.Auto.auto_photophysics'; the following exception was raised:
Traceback (most recent call last):
  File "/Users/david/anaconda/lib/python2.7/site-packages/Sphinx-1.3.1-py2.7.egg/sphinx/ext/autodoc.py", line 385, in import_object
    __import__(self.modname)
  File "/Users/david/python-microscopy/PYME/Analysis/Auto/auto_photophysics.py", line 8, in <module>
    from PYME.Analysis.LMVis.pipeline import Pipeline
  File "/Users/david/python-microscopy/PYME/Analysis/LMVis/pipeline.py", line 27, in <module>
    from PYME.Analysis.LMVis import renderers
  File "/Users/david/python-microscopy/PYME/Analysis/LMVis/renderers.py", line 33, in <module>
    from PYME.Analysis.QuadTree import QTrend
  File "/Users/david/python-microscopy/PYME/Analysis/QuadTree/__init__.py", line 25, in <module>
    from QTrend import *
  File "/Users/david/python-microscopy/PYME/Analysis/QuadTree/QTrend.py", line 28, in <module>
    def rendQT(ax, qt, maxDepth=-1, cmap=cm.hot, maxIsc = 1):
NameError: name 'cm' is not defined
/Users/david/python-microscopy/doc/api/Analysis/PYME.Analysis.BleachProfile.deMod.rst:4: WARNING: autodoc: failed to import module u'PYME.Analysis.BleachProfile.deMod'; the following exception was raised:
Traceback (most recent call last):
  File "/Users/david/anaconda/lib/python2.7/site-packages/Sphinx-1.3.1-py2.7.egg/sphinx/ext/autodoc.py", line 385, in import_object
    __import__(self.modname)
  File "/Users/david/python-microscopy/PYME/Analysis/BleachProfile/deMod.py", line 25, in <module>
    from scipy.integrate import odeint
ImportError: No module named integrate
/Users/david/python-microscopy/doc/api/Analysis/PYME.Analysis.BleachProfile.fitRecover.rst:4: WARNING: autodoc: failed to import module u'PYME.Analysis.BleachProfile.fitRecover'; the following exception was raised:
Traceback (most recent call last):
  File "/Users/david/anaconda/lib/python2.7/site-packages/Sphinx-1.3.1-py2.7.egg/sphinx/ext/autodoc.py", line 385, in import_object
    __import__(self.modname)
  File "/Users/david/python-microscopy/PYME/Analysis/BleachProfile/fitRecover.py", line 23, in <module>
    from . import intensProf
  File "/Users/david/python-microscopy/PYME/Analysis/BleachProfile/intensProf.py", line 29, in <module>
    from . import deMod
  File "/Users/david/python-microscopy/PYME/Analysis/BleachProfile/deMod.py", line 25, in <module>
    from scipy.integrate import odeint
ImportError: No module named integrate
/Users/david/python-microscopy/doc/api/Analysis/PYME.Analysis.BleachProfile.intensProf.rst:4: WARNING: autodoc: failed to import module u'PYME.Analysis.BleachProfile.intensProf'; the following exception was raised:
Traceback (most recent call last):
  File "/Users/david/anaconda/lib/python2.7/site-packages/Sphinx-1.3.1-py2.7.egg/sphinx/ext/autodoc.py", line 385, in import_object
    __import__(self.modname)
  File "/Users/david/python-microscopy/PYME/Analysis/BleachProfile/intensProf.py", line 29, in <module>
    from . import deMod
  File "/Users/david/python-microscopy/PYME/Analysis/BleachProfile/deMod.py", line 25, in <module>
    from scipy.integrate import odeint
ImportError: No module named integrate
/Users/david/python-microscopy/doc/api/Analysis/PYME.Analysis.BleachProfile.kinModels.rst:4: WARNING: autodoc: failed to import module u'PYME.Analysis.BleachProfile.kinModels'; the following exception was raised:
Traceback (most recent call last):
  File "/Users/david/anaconda/lib/python2.7/site-packages/Sphinx-1.3.1-py2.7.egg/sphinx/ext/autodoc.py", line 385, in import_object
    __import__(self.modname)
  File "/Users/david/python-microscopy/PYME/Analysis/BleachProfile/kinModels.py", line 24, in <module>
    from PYME.Analysis._fithelpers import *
  File "/Users/david/python-microscopy/PYME/Analysis/_fithelpers.py", line 25, in <module>
    import scipy.optimize as optimize
ImportError: No module named optimize
/Users/david/python-microscopy/doc/api/Analysis/PYME.Analysis.BleachProfile.rawIntensity.rst:4: WARNING: autodoc: failed to import module u'PYME.Analysis.BleachProfile.rawIntensity'; the following exception was raised:
Traceback (most recent call last):
  File "/Users/david/anaconda/lib/python2.7/site-packages/Sphinx-1.3.1-py2.7.egg/sphinx/ext/autodoc.py", line 385, in import_object
    __import__(self.modname)
  File "/Users/david/python-microscopy/PYME/Analysis/BleachProfile/rawIntensity.py", line 26, in <module>
    from PYME.Analysis._fithelpers import *
  File "/Users/david/python-microscopy/PYME/Analysis/_fithelpers.py", line 25, in <module>
    import scipy.optimize as optimize
ImportError: No module named optimize
[u'imageDensityAtDistance(A, mask, voxelsize=None, bins=100)', u':module: PYME.Analysis.Colocalisation.edtColoc', u'', u'', u'', u'Calculates the distribution of a label at varying distances from a mask.', u'Negative distances are on the inside of the mask.', u'', u'Parameters:', u'A - intensity image', u'mask - binary mask', u'voxelsize - size of the pixels/voxels - should be either a constant, or an iterable', u'            with a length equal to the number of dimensions in the data', u'bins - either a number of bins, or an array of bin edges', u'', u'Returns:', u'bn - integrated intensity in distance bin', u'bm - mean intensity in distance bin', u'bins - the bin edges']:10: ERROR: Unexpected indentation.
/Users/david/python-microscopy/PYME/Analysis/Colocalisation/edtColoc.py:docstring of PYME.Analysis.Colocalisation.edtColoc.imageDensityAtDistance:13: WARNING: Block quote ends without a blank line; unexpected unindent.
[u'pointDensityAtDistance(points, mask, voxelsize, maskOffset, bins=100)', u':module: PYME.Analysis.Colocalisation.edtColoc', u'', u'', u'', u'Calculates the distribution of a label at varying distances from a mask.', u'Negative distances are on the inside of the mask.', u'', u'Parameters:', u'points - array containing point coordinates', u'mask - binary mask', u'voxelsize - size of the pixels/voxels in mask - should be an iterable', u'            with a length equal to the number of dimensions in the data', u'maskOffset - iterable with lengh equal to number of dims giving coordinates (in point space)', u'             or the 0th pixel in the mask', u'bins - either a number of bins, or an array of bin edges', u'', u'Returns:', u'bn - integrated intensity in distance bin', u'bm - mean intensity in distance bin', u'bins - the bin edges']:10: ERROR: Unexpected indentation.
/Users/david/python-microscopy/PYME/Analysis/Colocalisation/edtColoc.py:docstring of PYME.Analysis.Colocalisation.edtColoc.pointDensityAtDistance:13: WARNING: Block quote ends without a blank line; unexpected unindent.
/Users/david/python-microscopy/PYME/Analysis/Colocalisation/edtColoc.py:docstring of PYME.Analysis.Colocalisation.edtColoc.pointDensityAtDistance:15: WARNING: Definition list ends without a blank line; unexpected unindent.
/Users/david/python-microscopy/doc/api/Analysis/PYME.Analysis.DeClump.testClump.rst:4: WARNING: autodoc: failed to import module u'PYME.Analysis.DeClump.testClump'; the following exception was raised:
Traceback (most recent call last):
  File "/Users/david/anaconda/lib/python2.7/site-packages/Sphinx-1.3.1-py2.7.egg/sphinx/ext/autodoc.py", line 385, in import_object
    __import__(self.modname)
  File "/Users/david/python-microscopy/PYME/Analysis/DeClump/testClump.py", line 29, in <module>
    t = arange(0, 200, .02)
NameError: name 'arange' is not defined
/Users/david/python-microscopy/doc/api/Analysis/PYME.Analysis.EdgeDB.edgeTest.rst:4: WARNING: autodoc: failed to import module u'PYME.Analysis.EdgeDB.edgeTest'; the following exception was raised:
Traceback (most recent call last):
  File "/Users/david/anaconda/lib/python2.7/site-packages/Sphinx-1.3.1-py2.7.egg/sphinx/ext/autodoc.py", line 385, in import_object
    __import__(self.modname)
  File "/Users/david/python-microscopy/PYME/Analysis/EdgeDB/edgeTest.py", line 30, in <module>
    x = rand(1e6)
NameError: name 'rand' is not defined
/Users/david/python-microscopy/doc/api/Analysis/PYME.Analysis.QuadTree.rst:18: WARNING: autodoc: failed to import module u'PYME.Analysis.QuadTree'; the following exception was raised:
Traceback (most recent call last):
  File "/Users/david/anaconda/lib/python2.7/site-packages/Sphinx-1.3.1-py2.7.egg/sphinx/ext/autodoc.py", line 385, in import_object
    __import__(self.modname)
  File "/Users/david/python-microscopy/PYME/Analysis/QuadTree/__init__.py", line 25, in <module>
    from QTrend import *
  File "/Users/david/python-microscopy/PYME/Analysis/QuadTree/QTrend.py", line 28, in <module>
    def rendQT(ax, qt, maxDepth=-1, cmap=cm.hot, maxIsc = 1):
NameError: name 'cm' is not defined
/Users/david/python-microscopy/doc/api/Analysis/PYME.Analysis.QuadTree.QTrend.rst:4: WARNING: autodoc: failed to import module u'PYME.Analysis.QuadTree.QTrend'; the following exception was raised:
Traceback (most recent call last):
  File "/Users/david/anaconda/lib/python2.7/site-packages/Sphinx-1.3.1-py2.7.egg/sphinx/ext/autodoc.py", line 385, in import_object
    __import__(self.modname)
  File "/Users/david/python-microscopy/PYME/Analysis/QuadTree/__init__.py", line 25, in <module>
    from QTrend import *
  File "/Users/david/python-microscopy/PYME/Analysis/QuadTree/QTrend.py", line 28, in <module>
    def rendQT(ax, qt, maxDepth=-1, cmap=cm.hot, maxIsc = 1):
NameError: name 'cm' is not defined
/Users/david/python-microscopy/doc/api/Analysis/PYME.Analysis.QuadTree.pointQT.rst:4: WARNING: autodoc: failed to import module u'PYME.Analysis.QuadTree.pointQT'; the following exception was raised:
Traceback (most recent call last):
  File "/Users/david/anaconda/lib/python2.7/site-packages/Sphinx-1.3.1-py2.7.egg/sphinx/ext/autodoc.py", line 385, in import_object
    __import__(self.modname)
  File "/Users/david/python-microscopy/PYME/Analysis/QuadTree/__init__.py", line 25, in <module>
    from QTrend import *
  File "/Users/david/python-microscopy/PYME/Analysis/QuadTree/QTrend.py", line 28, in <module>
    def rendQT(ax, qt, maxDepth=-1, cmap=cm.hot, maxIsc = 1):
NameError: name 'cm' is not defined
/Users/david/python-microscopy/doc/api/Analysis/PYME.Analysis.QuadTree.pointQTF.rst:4: WARNING: autodoc: failed to import module u'PYME.Analysis.QuadTree.pointQTF'; the following exception was raised:
Traceback (most recent call last):
  File "/Users/david/anaconda/lib/python2.7/site-packages/Sphinx-1.3.1-py2.7.egg/sphinx/ext/autodoc.py", line 385, in import_object
    __import__(self.modname)
  File "/Users/david/python-microscopy/PYME/Analysis/QuadTree/__init__.py", line 25, in <module>
    from QTrend import *
  File "/Users/david/python-microscopy/PYME/Analysis/QuadTree/QTrend.py", line 28, in <module>
    def rendQT(ax, qt, maxDepth=-1, cmap=cm.hot, maxIsc = 1):
NameError: name 'cm' is not defined
/Users/david/python-microscopy/doc/api/Analysis/PYME.Analysis.QuadTree.qtUtils.rst:4: WARNING: autodoc: failed to import module u'PYME.Analysis.QuadTree.qtUtils'; the following exception was raised:
Traceback (most recent call last):
  File "/Users/david/anaconda/lib/python2.7/site-packages/Sphinx-1.3.1-py2.7.egg/sphinx/ext/autodoc.py", line 385, in import_object
    __import__(self.modname)
  File "/Users/david/python-microscopy/PYME/Analysis/QuadTree/__init__.py", line 25, in <module>
    from QTrend import *
  File "/Users/david/python-microscopy/PYME/Analysis/QuadTree/QTrend.py", line 28, in <module>
    def rendQT(ax, qt, maxDepth=-1, cmap=cm.hot, maxIsc = 1):
NameError: name 'cm' is not defined
/Users/david/python-microscopy/doc/api/Analysis/PYME.Analysis.QuadTree.rendQT.rst:4: WARNING: autodoc: failed to import module u'PYME.Analysis.QuadTree.rendQT'; the following exception was raised:
Traceback (most recent call last):
  File "/Users/david/anaconda/lib/python2.7/site-packages/Sphinx-1.3.1-py2.7.egg/sphinx/ext/autodoc.py", line 385, in import_object
    __import__(self.modname)
  File "/Users/david/python-microscopy/PYME/Analysis/QuadTree/__init__.py", line 25, in <module>
    from QTrend import *
  File "/Users/david/python-microscopy/PYME/Analysis/QuadTree/QTrend.py", line 28, in <module>
    def rendQT(ax, qt, maxDepth=-1, cmap=cm.hot, maxIsc = 1):
NameError: name 'cm' is not defined
/Users/david/python-microscopy/doc/api/Analysis/PYME.Analysis.SoftRend.testTetrahedra.rst:4: WARNING: autodoc: failed to import module u'PYME.Analysis.SoftRend.testTetrahedra'; the following exception was raised:
Traceback (most recent call last):
  File "/Users/david/anaconda/lib/python2.7/site-packages/Sphinx-1.3.1-py2.7.egg/sphinx/ext/autodoc.py", line 385, in import_object
    __import__(self.modname)
  File "/Users/david/python-microscopy/PYME/Analysis/SoftRend/testTetrahedra.py", line 25, in <module>
    from PYME.Analysis.LMVis import gen3DTriangs
  File "/Users/david/python-microscopy/PYME/Analysis/LMVis/gen3DTriangs.py", line 74, in <module>
    def gen3DTriangs(x,y,z, sizeCutoff=inf, internalCull=True, pcut=inf):
NameError: name 'inf' is not defined
/Users/david/python-microscopy/doc/api/Analysis/PYME.Analysis.Test.fitTestJig.rst:4: WARNING: autodoc: failed to import module u'PYME.Analysis.Test.fitTestJig'; the following exception was raised:
Traceback (most recent call last):
  File "/Users/david/anaconda/lib/python2.7/site-packages/Sphinx-1.3.1-py2.7.egg/sphinx/ext/autodoc.py", line 385, in import_object
    __import__(self.modname)
  File "/Users/david/python-microscopy/PYME/Analysis/Test/fitTestJig.py", line 25, in <module>
    from PYME.Acquire.Hardware.Simulator.fakeCam import NoiseMaker
  File "/Users/david/python-microscopy/PYME/Acquire/Hardware/Simulator/fakeCam.py", line 24, in <module>
    from . import rend_im
  File "/Users/david/python-microscopy/PYME/Acquire/Hardware/Simulator/rend_im.py", line 101, in <module>
    genTheoreticalModel(MetaData.TIRFDefault)
  File "/Users/david/python-microscopy/PYME/Acquire/Hardware/Simulator/rend_im.py", line 82, in genTheoreticalModel
    IntXVals = 1e3*md.voxelsize.x*mgrid[-150:150]
NameError: global name 'mgrid' is not defined
/Users/david/python-microscopy/doc/api/Analysis/PYME.Analysis.Test.fitTestJigWC.rst:4: WARNING: autodoc: failed to import module u'PYME.Analysis.Test.fitTestJigWC'; the following exception was raised:
Traceback (most recent call last):
  File "/Users/david/anaconda/lib/python2.7/site-packages/Sphinx-1.3.1-py2.7.egg/sphinx/ext/autodoc.py", line 385, in import_object
    __import__(self.modname)
  File "/Users/david/python-microscopy/PYME/Analysis/Test/fitTestJigWC.py", line 25, in <module>
    from PYME.Acquire.Hardware.Simulator.fakeCam import NoiseMaker
  File "/Users/david/python-microscopy/PYME/Acquire/Hardware/Simulator/fakeCam.py", line 24, in <module>
    from . import rend_im
  File "/Users/david/python-microscopy/PYME/Acquire/Hardware/Simulator/rend_im.py", line 101, in <module>
    genTheoreticalModel(MetaData.TIRFDefault)
  File "/Users/david/python-microscopy/PYME/Acquire/Hardware/Simulator/rend_im.py", line 82, in genTheoreticalModel
    IntXVals = 1e3*md.voxelsize.x*mgrid[-150:150]
NameError: global name 'mgrid' is not defined
/Users/david/python-microscopy/PYME/Analysis/angleFilter.py:docstring of PYME.Analysis.angleFilter:5: WARNING: Inline emphasis start-string without end-string.
/Users/david/python-microscopy/doc/api/Analysis/PYME.Analysis.fusionUtils.rst:4: WARNING: autodoc: failed to import module u'PYME.Analysis.fusionUtils'; the following exception was raised:
Traceback (most recent call last):
  File "/Users/david/anaconda/lib/python2.7/site-packages/Sphinx-1.3.1-py2.7.egg/sphinx/ext/autodoc.py", line 385, in import_object
    __import__(self.modname)
  File "/Users/david/python-microscopy/PYME/Analysis/fusionUtils.py", line 11, in <module>
    import PYME.Analysis.trackUtils as trackUtils
  File "/Users/david/python-microscopy/PYME/Analysis/trackUtils.py", line 25, in <module>
    import mpld3
  File "/Users/david/anaconda/lib/python2.7/site-packages/mpld3/__init__.py", line 43, in <module>
    from ._display import *
  File "/Users/david/anaconda/lib/python2.7/site-packages/mpld3/_display.py", line 9, in <module>
    from .mplexporter import Exporter
  File "/Users/david/anaconda/lib/python2.7/site-packages/mpld3/mplexporter/__init__.py", line 1, in <module>
    from .renderers import Renderer
  File "/Users/david/anaconda/lib/python2.7/site-packages/mpld3/mplexporter/renderers/__init__.py", line 9, in <module>
    from .base import Renderer
  File "/Users/david/anaconda/lib/python2.7/site-packages/mpld3/mplexporter/renderers/base.py", line 8, in <module>
    from .. import utils
  File "/Users/david/anaconda/lib/python2.7/site-packages/mpld3/mplexporter/utils.py", line 15, in <module>
    from matplotlib.path import Path
ImportError: No module named path
/Users/david/python-microscopy/doc/api/Analysis/PYME.Analysis.multicolourMeta.rst:4: WARNING: autodoc: failed to import module u'PYME.Analysis.multicolourMeta'; the following exception was raised:
Traceback (most recent call last):
  File "/Users/david/anaconda/lib/python2.7/site-packages/Sphinx-1.3.1-py2.7.egg/sphinx/ext/autodoc.py", line 385, in import_object
    __import__(self.modname)
  File "/Users/david/python-microscopy/PYME/Analysis/multicolourMeta.py", line 23, in <module>
    from PYME.SampleDB import populateStats
ImportError: No module named SampleDB
/Users/david/python-microscopy/doc/api/Analysis/PYME.Analysis.ofind.rst:4: WARNING: autodoc: failed to import module u'PYME.Analysis.ofind'; the following exception was raised:
Traceback (most recent call last):
  File "/Users/david/anaconda/lib/python2.7/site-packages/Sphinx-1.3.1-py2.7.egg/sphinx/ext/autodoc.py", line 385, in import_object
    __import__(self.modname)
  File "/Users/david/python-microscopy/PYME/Analysis/ofind.py", line 56, in <module>
    weightsLowpass = calc_gauss_weights(filtRadLowpass)
  File "/Users/david/python-microscopy/PYME/Analysis/ofind.py", line 39, in calc_gauss_weights
    weights[lw] = 1.0
TypeError: 'Mock' object does not support item assignment
/Users/david/python-microscopy/doc/api/Analysis/PYME.Analysis.ofind_pri.rst:4: WARNING: autodoc: failed to import module u'PYME.Analysis.ofind_pri'; the following exception was raised:
Traceback (most recent call last):
  File "/Users/david/anaconda/lib/python2.7/site-packages/Sphinx-1.3.1-py2.7.egg/sphinx/ext/autodoc.py", line 385, in import_object
    __import__(self.modname)
  File "/Users/david/python-microscopy/PYME/Analysis/ofind_pri.py", line 62, in <module>
    weightsLowpass = calc_gauss_weights(filtRadLowpass)
  File "/Users/david/python-microscopy/PYME/Analysis/ofind_pri.py", line 45, in calc_gauss_weights
    weights[lw] = 1.0
TypeError: 'Mock' object does not support item assignment
/Users/david/python-microscopy/doc/api/Analysis/PYME.Analysis.ofind_split.rst:4: WARNING: autodoc: failed to import module u'PYME.Analysis.ofind_split'; the following exception was raised:
Traceback (most recent call last):
  File "/Users/david/anaconda/lib/python2.7/site-packages/Sphinx-1.3.1-py2.7.egg/sphinx/ext/autodoc.py", line 385, in import_object
    __import__(self.modname)
  File "/Users/david/python-microscopy/PYME/Analysis/ofind_split.py", line 56, in <module>
    weightsLowpass = calc_gauss_weights(filtRadLowpass)
  File "/Users/david/python-microscopy/PYME/Analysis/ofind_split.py", line 39, in calc_gauss_weights
    weights[lw] = 1.0
TypeError: 'Mock' object does not support item assignment
/Users/david/python-microscopy/doc/api/Analysis/PYME.Analysis.ofind_xcorr.rst:4: WARNING: autodoc: failed to import module u'PYME.Analysis.ofind_xcorr'; the following exception was raised:
Traceback (most recent call last):
  File "/Users/david/anaconda/lib/python2.7/site-packages/Sphinx-1.3.1-py2.7.egg/sphinx/ext/autodoc.py", line 385, in import_object
    __import__(self.modname)
  File "/Users/david/python-microscopy/PYME/Analysis/ofind_xcorr.py", line 25, in <module>
    import scipy.signal
ImportError: No module named signal
/Users/david/python-microscopy/doc/api/Analysis/PYME.Analysis.ofind_xcorr_fw.rst:4: WARNING: autodoc: failed to import module u'PYME.Analysis.ofind_xcorr_fw'; the following exception was raised:
Traceback (most recent call last):
  File "/Users/david/anaconda/lib/python2.7/site-packages/Sphinx-1.3.1-py2.7.egg/sphinx/ext/autodoc.py", line 385, in import_object
    __import__(self.modname)
  File "/Users/david/python-microscopy/PYME/Analysis/ofind_xcorr_fw.py", line 25, in <module>
    import scipy.signal
ImportError: No module named signal
/Users/david/python-microscopy/PYME/Analysis/optic_flow.py:docstring of PYME.Analysis.optic_flow.reg_of:11: ERROR: Error in "rubric" directive:
no content permitted.

.. rubric:: Notes

    See "Optical Flow Estimation", Fleet and Weiss 2006 for underlying maths. Our
    implementation is based on Section 2, "Basic gradient-based estimation", and 
    attempts to find a least-squares which minimizes:

    .. math:: E(        ilde{u}) = \sum_{       ilde{x}}g(      ilde{x})\left[  ilde{u} \cdot
/Users/david/python-microscopy/PYME/Analysis/optic_flow.py:docstring of PYME.Analysis.optic_flow.reg_of:18: WARNING: Explicit markup ends without a blank line; unexpected unindent.
/Users/david/python-microscopy/PYME/Analysis/optic_flow.py:docstring of PYME.Analysis.optic_flow.reg_of:26: WARNING: Block quote ends without a blank line; unexpected unindent.
/Users/david/python-microscopy/doc/api/Analysis/PYME.Analysis.pSpaceMap.rst:4: WARNING: autodoc: failed to import module u'PYME.Analysis.pSpaceMap'; the following exception was raised:
Traceback (most recent call last):
  File "/Users/david/anaconda/lib/python2.7/site-packages/Sphinx-1.3.1-py2.7.egg/sphinx/ext/autodoc.py", line 385, in import_object
    __import__(self.modname)
  File "/Users/david/python-microscopy/PYME/Analysis/pSpaceMap.py", line 23, in <module>
    xvs = 70*arange(-2.01, 2,.1)
NameError: name 'arange' is not defined
/Users/david/python-microscopy/doc/api/Analysis/PYME.Analysis.pointFitConfoc.rst:4: WARNING: autodoc: failed to import module u'PYME.Analysis.pointFitConfoc'; the following exception was raised:
Traceback (most recent call last):
  File "/Users/david/anaconda/lib/python2.7/site-packages/Sphinx-1.3.1-py2.7.egg/sphinx/ext/autodoc.py", line 385, in import_object
    __import__(self.modname)
  File "/Users/david/python-microscopy/PYME/Analysis/pointFitConfoc.py", line 29, in <module>
    from PYME.Analysis.FitFactories.Gauss3DFitR import FitFactory
  File "/Users/david/python-microscopy/PYME/Analysis/FitFactories/Gauss3DFitR.py", line 28, in <module>
    from PYME.Analysis._fithelpers import *
  File "/Users/david/python-microscopy/PYME/Analysis/_fithelpers.py", line 25, in <module>
    import scipy.optimize as optimize
ImportError: No module named optimize
/Users/david/python-microscopy/doc/api/Analysis/PYME.Analysis.remFitBuf.rst:4: WARNING: autodoc: failed to import module u'PYME.Analysis.remFitBuf'; the following exception was raised:
Traceback (most recent call last):
  File "/Users/david/anaconda/lib/python2.7/site-packages/Sphinx-1.3.1-py2.7.egg/sphinx/ext/autodoc.py", line 385, in import_object
    __import__(self.modname)
  File "/Users/david/python-microscopy/PYME/Analysis/remFitBuf.py", line 25, in <module>
    from PYME.Analysis import ofind
  File "/Users/david/python-microscopy/PYME/Analysis/ofind.py", line 56, in <module>
    weightsLowpass = calc_gauss_weights(filtRadLowpass)
  File "/Users/david/python-microscopy/PYME/Analysis/ofind.py", line 39, in calc_gauss_weights
    weights[lw] = 1.0
TypeError: 'Mock' object does not support item assignment
/Users/david/python-microscopy/doc/api/Analysis/PYME.Analysis.svmSegment.rst:4: WARNING: autodoc: failed to import module u'PYME.Analysis.svmSegment'; the following exception was raised:
Traceback (most recent call last):
  File "/Users/david/anaconda/lib/python2.7/site-packages/Sphinx-1.3.1-py2.7.egg/sphinx/ext/autodoc.py", line 385, in import_object
    __import__(self.modname)
  File "/Users/david/python-microscopy/PYME/Analysis/svmSegment.py", line 14, in <module>
    import sklearn
  File "/Users/david/anaconda/lib/python2.7/site-packages/sklearn/__init__.py", line 57, in <module>
    from .base import clone
  File "/Users/david/anaconda/lib/python2.7/site-packages/sklearn/base.py", line 11, in <module>
    from .utils.fixes import signature
  File "/Users/david/anaconda/lib/python2.7/site-packages/sklearn/utils/__init__.py", line 7, in <module>
    from scipy.sparse import issparse
ImportError: No module named sparse
/Users/david/python-microscopy/doc/api/Analysis/PYME.Analysis.trackUtils.rst:4: WARNING: autodoc: failed to import module u'PYME.Analysis.trackUtils'; the following exception was raised:
Traceback (most recent call last):
  File "/Users/david/anaconda/lib/python2.7/site-packages/Sphinx-1.3.1-py2.7.egg/sphinx/ext/autodoc.py", line 385, in import_object
    __import__(self.modname)
  File "/Users/david/python-microscopy/PYME/Analysis/trackUtils.py", line 25, in <module>
    import mpld3
  File "/Users/david/anaconda/lib/python2.7/site-packages/mpld3/__init__.py", line 41, in <module>
    from . import plugins
ImportError: cannot import name plugins
/Users/david/python-microscopy/doc/api/Analysis/PYME.Analysis.twoColDep.rst:4: WARNING: autodoc: failed to import module u'PYME.Analysis.twoColDep'; the following exception was raised:
Traceback (most recent call last):
  File "/Users/david/anaconda/lib/python2.7/site-packages/Sphinx-1.3.1-py2.7.egg/sphinx/ext/autodoc.py", line 385, in import_object
    __import__(self.modname)
  File "/Users/david/python-microscopy/PYME/Analysis/twoColDep.py", line 26, in <module>
    from PYME.Analysis import ofind
  File "/Users/david/python-microscopy/PYME/Analysis/ofind.py", line 56, in <module>
    weightsLowpass = calc_gauss_weights(filtRadLowpass)
  File "/Users/david/python-microscopy/PYME/Analysis/ofind.py", line 39, in calc_gauss_weights
    weights[lw] = 1.0
TypeError: 'Mock' object does not support item assignment
/Users/david/python-microscopy/doc/api/Analysis/PYME.Analysis.twoColour.rst:4: WARNING: autodoc: failed to import module u'PYME.Analysis.twoColour'; the following exception was raised:
Traceback (most recent call last):
  File "/Users/david/anaconda/lib/python2.7/site-packages/Sphinx-1.3.1-py2.7.egg/sphinx/ext/autodoc.py", line 385, in import_object
    __import__(self.modname)
  File "/Users/david/python-microscopy/PYME/Analysis/twoColour.py", line 27, in <module>
    from PYME.Analysis import ofind
  File "/Users/david/python-microscopy/PYME/Analysis/ofind.py", line 56, in <module>
    weightsLowpass = calc_gauss_weights(filtRadLowpass)
  File "/Users/david/python-microscopy/PYME/Analysis/ofind.py", line 39, in calc_gauss_weights
    weights[lw] = 1.0
TypeError: 'Mock' object does not support item assignment
/Users/david/python-microscopy/doc/api/DSView/PYME.DSView.rst:15: WARNING: toctree contains reference to nonexisting document u'api/DSView/PYME.DSView.viewpanellite'
/Users/david/python-microscopy/doc/api/DSView/PYME.DSView.LUT.test_lut.rst:4: WARNING: autodoc: failed to import module u'PYME.DSView.LUT.test_lut'; the following exception was raised:
Traceback (most recent call last):
  File "/Users/david/anaconda/lib/python2.7/site-packages/Sphinx-1.3.1-py2.7.egg/sphinx/ext/autodoc.py", line 385, in import_object
    __import__(self.modname)
  File "/Users/david/python-microscopy/PYME/DSView/LUT/test_lut.py", line 27, in <module>
    lut1 = (255*cm.gray(linspace(0,1,256))[:,:3].T).astype('uint8').copy()
NameError: name 'cm' is not defined
/Users/david/python-microscopy/doc/api/DSView/PYME.DSView.modules.LMAnalysis.rst:4: WARNING: autodoc: failed to import module u'PYME.DSView.modules.LMAnalysis'; the following exception was raised:
Traceback (most recent call last):
  File "/Users/david/anaconda/lib/python2.7/site-packages/Sphinx-1.3.1-py2.7.egg/sphinx/ext/autodoc.py", line 385, in import_object
    __import__(self.modname)
  File "/Users/david/python-microscopy/PYME/DSView/modules/LMAnalysis.py", line 24, in <module>
    from PYME.Analysis import remFitBuf
  File "/Users/david/python-microscopy/PYME/Analysis/remFitBuf.py", line 25, in <module>
    from PYME.Analysis import ofind
  File "/Users/david/python-microscopy/PYME/Analysis/ofind.py", line 56, in <module>
    weightsLowpass = calc_gauss_weights(filtRadLowpass)
  File "/Users/david/python-microscopy/PYME/Analysis/ofind.py", line 39, in calc_gauss_weights
    weights[lw] = 1.0
TypeError: 'Mock' object does not support item assignment
/Users/david/python-microscopy/doc/api/DSView/PYME.DSView.modules.LMDisplay.rst:4: WARNING: autodoc: failed to import module u'PYME.DSView.modules.LMDisplay'; the following exception was raised:
Traceback (most recent call last):
  File "/Users/david/anaconda/lib/python2.7/site-packages/Sphinx-1.3.1-py2.7.egg/sphinx/ext/autodoc.py", line 385, in import_object
    __import__(self.modname)
  File "/Users/david/python-microscopy/PYME/DSView/modules/LMDisplay.py", line 24, in <module>
    from PYME.Analysis.LMVis import gl_render
  File "/Users/david/python-microscopy/PYME/Analysis/LMVis/gl_render.py", line 30, in <module>
    from OpenGL.GL import *
  File "/Users/david/anaconda/lib/python2.7/site-packages/OpenGL/GL/__init__.py", line 3, in <module>
    from OpenGL.GL.VERSION.GL_1_1 import *
  File "/Users/david/anaconda/lib/python2.7/site-packages/OpenGL/GL/VERSION/GL_1_1.py", line 10, in <module>
    from OpenGL import platform, constants, constant, arrays
  File "/Users/david/anaconda/lib/python2.7/site-packages/OpenGL/arrays/__init__.py", line 22, in <module>
    formathandler.FormatHandler.loadAll()
  File "/Users/david/anaconda/lib/python2.7/site-packages/OpenGL/arrays/formathandler.py", line 28, in loadAll
    cls.loadPlugin( entrypoint )
  File "/Users/david/anaconda/lib/python2.7/site-packages/OpenGL/arrays/formathandler.py", line 35, in loadPlugin
    plugin_class = entrypoint.load()
  File "/Users/david/anaconda/lib/python2.7/site-packages/OpenGL/plugins.py", line 14, in load
    return importByName( self.import_path )
  File "/Users/david/anaconda/lib/python2.7/site-packages/OpenGL/plugins.py", line 28, in importByName
    module = __import__( ".".join(moduleName), {}, {}, moduleName)
  File "/Users/david/anaconda/lib/python2.7/site-packages/OpenGL/arrays/numpymodule.py", line 209, in <module>
    lookupDtype(USHORT_TYPE): constants.GL_UNSIGNED_SHORT,
NameError: name 'USHORT_TYPE' is not defined
/Users/david/python-microscopy/doc/api/DSView/PYME.DSView.modules.flowView.rst:4: WARNING: autodoc: failed to import module u'PYME.DSView.modules.flowView'; the module executes module level statement and it might call sys.exit().
/Users/david/python-microscopy/doc/api/DSView/PYME.DSView.modules.graphViewPanel.rst:4: WARNING: autodoc: failed to import module u'PYME.DSView.modules.graphViewPanel'; the following exception was raised:
Traceback (most recent call last):
  File "/Users/david/anaconda/lib/python2.7/site-packages/Sphinx-1.3.1-py2.7.egg/sphinx/ext/autodoc.py", line 385, in import_object
    __import__(self.modname)
  File "/Users/david/python-microscopy/PYME/DSView/modules/graphViewPanel.py", line 29, in <module>
    from matplotlib.backends.backend_wxagg import FigureCanvasWxAgg as FigureCanvas
ImportError: No module named backends.backend_wxagg
/Users/david/python-microscopy/doc/api/DSView/PYME.DSView.modules.particleTracking.rst:4: WARNING: autodoc: failed to import module u'PYME.DSView.modules.particleTracking'; the module executes module level statement and it might call sys.exit().
/Users/david/python-microscopy/doc/api/DSView/PYME.DSView.modules.psfGeneration.rst:4: WARNING: autodoc: failed to import module u'PYME.DSView.modules.psfGeneration'; the following exception was raised:
Traceback (most recent call last):
  File "/Users/david/anaconda/lib/python2.7/site-packages/Sphinx-1.3.1-py2.7.egg/sphinx/ext/autodoc.py", line 385, in import_object
    __import__(self.modname)
  File "/Users/david/python-microscopy/PYME/DSView/modules/psfGeneration.py", line 27, in <module>
    from enthought.traits.api import HasTraits, Float, Int, List, Instance, Property
ImportError: No module named enthought.traits.api
/Users/david/python-microscopy/doc/api/DSView/PYME.DSView.modules.psfTools.rst:4: WARNING: autodoc: failed to import module u'PYME.DSView.modules.psfTools'; the module executes module level statement and it might call sys.exit().
/Users/david/python-microscopy/doc/api/DSView/PYME.DSView.modules.pupilTools.rst:4: WARNING: autodoc: failed to import module u'PYME.DSView.modules.pupilTools'; the module executes module level statement and it might call sys.exit().
/Users/david/python-microscopy/doc/api/DSView/PYME.DSView.modules.pupilView.rst:4: WARNING: autodoc: failed to import module u'PYME.DSView.modules.pupilView'; the following exception was raised:
Traceback (most recent call last):
  File "/Users/david/anaconda/lib/python2.7/site-packages/Sphinx-1.3.1-py2.7.egg/sphinx/ext/autodoc.py", line 385, in import_object
    __import__(self.modname)
  File "/Users/david/python-microscopy/PYME/DSView/modules/pupilView.py", line 29, in <module>
    from matplotlib.backends.backend_wxagg import FigureCanvasWxAgg as FigureCanvas
ImportError: No module named backends.backend_wxagg
/Users/david/python-microscopy/doc/api/DSView/PYME.DSView.modules.recipes.rst:4: WARNING: autodoc: failed to import module u'PYME.DSView.modules.recipes'; the module executes module level statement and it might call sys.exit().
/Users/david/python-microscopy/doc/api/Deconv/PYME.Deconv.block_dec.rst:4: WARNING: autodoc: failed to import module u'PYME.Deconv.block_dec'; the following exception was raised:
Traceback (most recent call last):
  File "/Users/david/anaconda/lib/python2.7/site-packages/Sphinx-1.3.1-py2.7.egg/sphinx/ext/autodoc.py", line 385, in import_object
    __import__(self.modname)
  File "/Users/david/python-microscopy/PYME/Deconv/block_dec.py", line 25, in <module>
    import tcluster
  File "/Users/david/python-microscopy/PYME/Deconv/tcluster.py", line 26, in <module>
    import scipy.cow.sync_cluster
ImportError: No module named sync_cluster
[u'dec()', u':module: PYME.Deconv.dec', u'', u'', u'', u'', u'Base deconvolution class, implementing a variant of the ICTM algorithm.', u'ie. find f such that:', u'   ||Af-d||^2 + lamb^2||L(f - fdef)||^2', u'is minimised', u'', u'Note that this is nominally for Gaussian distributed noise, although can be', u'adapted by adding a weighting to the misfit term.', u'', u'Derived classed should additionally define the following methods:', u'AFunc - the forward mapping (computes Af)', u'AHFunc - conjugate transpose of forward mapping (computes \x08ar{A}^T f)', u'LFunc - the likelihood function', u'LHFunc - conj. transpose of likelihood function', u'', u'see dec_conv for an implementation of conventional image deconvolution with a', u'measured, spatially invariant PSF', u'', u'', u'.. py:method:: dec.deconv(data, lamb, num_iters=10, weights=1, alpha=None, bg=0)', u'   :module: PYME.Deconv.dec', u'', u'   ', u'   ', u'   This is what you actually call to do the deconvolution.', u'   parameters are:', u'   ', u'   data - the raw data', u'   lamb - the regularisation parameter', u'   num_iters - number of iterations (note that the convergence is fast when', u'               compared to many algorithms - e.g Richardson-Lucy - and the', u'               default of 10 will usually already give a reasonable result)', u'   ', u'   alpha - PSF phase - hacked in for variable phase 4Pi deconvolution, should', u'           really be refactored out into the dec_4pi classes.', u'   ', u'', u'.. py:method:: dec.deconvp(args)', u'   :module: PYME.Deconv.dec', u'', u'   ', u'   ', u'   convenience function for deconvolving in parallel using processing.Pool.map', u'   ', u'   ', u'', u'.. py:method:: dec.sim_pic(data, alpha)', u'   :module: PYME.Deconv.dec', u'', u'   ', u'   ', u'   Do the forward transform to simulate a picture. Currently with 4Pi cruft.', u'   ', u'   ', u'', u'.. py:method:: dec.startGuess(data)', u'   :module: PYME.Deconv.dec', u'', u'   ', u'   ', u'   starting guess for deconvolution - can be overridden in derived classes', u'   but the data itself is usually a pretty good guess.', u'   ', u'   ', u'', u'.. py:method:: dec.subsearch(f0, res, fdef, Afunc, Lfunc, lam, S)', u'   :module: PYME.Deconv.dec', u'', u'   ', u'   ', u'   minimise in subspace - this is the bit which gets called on each iteration', u'   to work out what the next step is going to be. See Inverse Problems text for details.']:5: ERROR: Unexpected indentation.
/Users/david/python-microscopy/PYME/Deconv/dec.py:docstring of PYME.Deconv.dec.dec:8: WARNING: Block quote ends without a blank line; unexpected unindent.
[u'dec.deconv(data, lamb, num_iters=10, weights=1, alpha=None, bg=0)', u':module: PYME.Deconv.dec', u'', u'This is what you actually call to do the deconvolution.', u'parameters are:', u'', u'data - the raw data', u'lamb - the regularisation parameter', u'num_iters - number of iterations (note that the convergence is fast when', u'            compared to many algorithms - e.g Richardson-Lucy - and the', u'            default of 10 will usually already give a reasonable result)', u'', u'alpha - PSF phase - hacked in for variable phase 4Pi deconvolution, should', u'        really be refactored out into the dec_4pi classes.']:9: ERROR: Unexpected indentation.
[u'dec()', u':module: PYME.Deconv.deccs', u'', u'', u'', u'', u'Base deconvolution class, implementing a variant of the ICTM algorithm.', u'ie. find f such that:', u'   ||Af-d||^2 + lamb^2||L(f - fdef)||^2', u'is minimised', u'', u'Note that this is nominally for Gaussian distributed noise, although can be', u'adapted by adding a weighting to the misfit term.', u'', u'Derived classed should additionally define the following methods:', u'AFunc - the forward mapping (computes Af)', u'AHFunc - conjugate transpose of forward mapping (computes \x08ar{A}^T f)', u'LFunc - the likelihood function', u'LHFunc - conj. transpose of likelihood function', u'', u'see dec_conv for an implementation of conventional image deconvolution with a', u'measured, spatially invariant PSF', u'', u'', u'.. py:method:: dec.deconv(data, lamb, num_iters=10, weights=1, k=0, k2=0)', u'   :module: PYME.Deconv.deccs', u'', u'   ', u'   ', u'   This is what you actually call to do the deconvolution.', u'   parameters are:', u'   ', u'   data - the raw data', u'   lamb - the regularisation parameter', u'   num_iters - number of iterations (note that the convergence is fast when', u'               compared to many algorithms - e.g Richardson-Lucy - and the', u'               default of 10 will usually already give a reasonable result)', u'   ', u'   alpha - PSF phase - hacked in for variable phase 4Pi deconvolution, should', u'           really be refactored out into the dec_4pi classes.', u'   ', u'', u'.. py:method:: dec.sim_pic(data, alpha)', u'   :module: PYME.Deconv.deccs', u'', u'   ', u'   ', u'   Do the forward transform to simulate a picture. Currently with 4Pi cruft.', u'   ', u'   ', u'', u'.. py:method:: dec.startGuess(data)', u'   :module: PYME.Deconv.deccs', u'', u'   ', u'   ', u'   starting guess for deconvolution - can be overridden in derived classes', u'   but the data itself is usually a pretty good guess.', u'   ', u'   ', u'', u'.. py:method:: dec.subsearch(f0, res, fdef, Afunc, Lfunc, lam2, S)', u'   :module: PYME.Deconv.deccs', u'', u'   ', u'   ', u'   minimise in subspace - this is the bit which gets called on each iteration', u'   to work out what the next step is going to be. See Inverse Problems text for details.']:5: ERROR: Unexpected indentation.
/Users/david/python-microscopy/PYME/Deconv/deccs.py:docstring of PYME.Deconv.deccs.dec:8: WARNING: Block quote ends without a blank line; unexpected unindent.
[u'dec.deconv(data, lamb, num_iters=10, weights=1, k=0, k2=0)', u':module: PYME.Deconv.deccs', u'', u'This is what you actually call to do the deconvolution.', u'parameters are:', u'', u'data - the raw data', u'lamb - the regularisation parameter', u'num_iters - number of iterations (note that the convergence is fast when', u'            compared to many algorithms - e.g Richardson-Lucy - and the', u'            default of 10 will usually already give a reasonable result)', u'', u'alpha - PSF phase - hacked in for variable phase 4Pi deconvolution, should', u'        really be refactored out into the dec_4pi classes.']:9: ERROR: Unexpected indentation.
[u'dec()', u':module: PYME.Deconv.deccs2', u'', u'', u'', u'', u'Base deconvolution class, implementing a variant of the ICTM algorithm.', u'ie. find f such that:', u'   ||Af-d||^2 + lamb^2||L(f - fdef)||^2', u'is minimised', u'', u'Note that this is nominally for Gaussian distributed noise, although can be', u'adapted by adding a weighting to the misfit term.', u'', u'Derived classed should additionally define the following methods:', u'AFunc - the forward mapping (computes Af)', u'AHFunc - conjugate transpose of forward mapping (computes \x08ar{A}^T f)', u'LFunc - the likelihood function', u'LHFunc - conj. transpose of likelihood function', u'', u'see dec_conv for an implementation of conventional image deconvolution with a', u'measured, spatially invariant PSF', u'', u'', u'.. py:method:: dec.deconv(data, lamb, num_iters=10, weights=1, inner_iters=10, k=0, k2=0)', u'   :module: PYME.Deconv.deccs2', u'', u'   ', u'   ', u'   This is what you actually call to do the deconvolution.', u'   parameters are:', u'   ', u'   data - the raw data', u'   lamb - the regularisation parameter', u'   num_iters - number of iterations (note that the convergence is fast when', u'               compared to many algorithms - e.g Richardson-Lucy - and the', u'               default of 10 will usually already give a reasonable result)', u'   ', u'   alpha - PSF phase - hacked in for variable phase 4Pi deconvolution, should', u'           really be refactored out into the dec_4pi classes.', u'   ', u'', u'.. py:method:: dec.sim_pic(data, alpha)', u'   :module: PYME.Deconv.deccs2', u'', u'   ', u'   ', u'   Do the forward transform to simulate a picture. Currently with 4Pi cruft.', u'   ', u'   ', u'', u'.. py:method:: dec.startGuess(data)', u'   :module: PYME.Deconv.deccs2', u'', u'   ', u'   ', u'   starting guess for deconvolution - can be overridden in derived classes', u'   but the data itself is usually a pretty good guess.', u'   ', u'   ', u'', u'.. py:method:: dec.subsearch(f0, res, fdef, Afunc, Lfunc, lam2, S)', u'   :module: PYME.Deconv.deccs2', u'', u'   ', u'   ', u'   minimise in subspace - this is the bit which gets called on each iteration', u'   to work out what the next step is going to be. See Inverse Problems text for details.']:5: ERROR: Unexpected indentation.
/Users/david/python-microscopy/PYME/Deconv/deccs2.py:docstring of PYME.Deconv.deccs2.dec:8: WARNING: Block quote ends without a blank line; unexpected unindent.
[u'dec.deconv(data, lamb, num_iters=10, weights=1, inner_iters=10, k=0, k2=0)', u':module: PYME.Deconv.deccs2', u'', u'This is what you actually call to do the deconvolution.', u'parameters are:', u'', u'data - the raw data', u'lamb - the regularisation parameter', u'num_iters - number of iterations (note that the convergence is fast when', u'            compared to many algorithms - e.g Richardson-Lucy - and the', u'            default of 10 will usually already give a reasonable result)', u'', u'alpha - PSF phase - hacked in for variable phase 4Pi deconvolution, should', u'        really be refactored out into the dec_4pi classes.']:9: ERROR: Unexpected indentation.
[u'dec()', u':module: PYME.Deconv.deccs_mc', u'', u'', u'', u'', u'Base deconvolution class, implementing a variant of the ICTM algorithm.', u'ie. find f such that:', u'   ||Af-d||^2 + lamb^2||L(f - fdef)||^2', u'is minimised', u'', u'Note that this is nominally for Gaussian distributed noise, although can be', u'adapted by adding a weighting to the misfit term.', u'', u'Derived classed should additionally define the following methods:', u'AFunc - the forward mapping (computes Af)', u'AHFunc - conjugate transpose of forward mapping (computes \x08ar{A}^T f)', u'LFunc - the likelihood function', u'LHFunc - conj. transpose of likelihood function', u'', u'see dec_conv for an implementation of conventional image deconvolution with a', u'measured, spatially invariant PSF', u'', u'', u'.. py:method:: dec.deconv(data, lamb, num_iters=10, weights=1, k=0, k2=0)', u'   :module: PYME.Deconv.deccs_mc', u'', u'   ', u'   ', u'   This is what you actually call to do the deconvolution.', u'   parameters are:', u'   ', u'   data - the raw data', u'   lamb - the regularisation parameter', u'   num_iters - number of iterations (note that the convergence is fast when', u'               compared to many algorithms - e.g Richardson-Lucy - and the', u'               default of 10 will usually already give a reasonable result)', u'   ', u'   alpha - PSF phase - hacked in for variable phase 4Pi deconvolution, should', u'           really be refactored out into the dec_4pi classes.', u'   ', u'', u'.. py:method:: dec.sim_pic(data, alpha)', u'   :module: PYME.Deconv.deccs_mc', u'', u'   ', u'   ', u'   Do the forward transform to simulate a picture. Currently with 4Pi cruft.', u'   ', u'   ', u'', u'.. py:method:: dec.startGuess(data)', u'   :module: PYME.Deconv.deccs_mc', u'', u'   ', u'   ', u'   starting guess for deconvolution - can be overridden in derived classes', u'   but the data itself is usually a pretty good guess.', u'   ', u'   ', u'', u'.. py:method:: dec.subsearch(f0, res, fdef, Afunc, Lfunc, lam2, S)', u'   :module: PYME.Deconv.deccs_mc', u'', u'   ', u'   ', u'   minimise in subspace - this is the bit which gets called on each iteration', u'   to work out what the next step is going to be. See Inverse Problems text for details.']:5: ERROR: Unexpected indentation.
/Users/david/python-microscopy/PYME/Deconv/deccs_mc.py:docstring of PYME.Deconv.deccs_mc.dec:8: WARNING: Block quote ends without a blank line; unexpected unindent.
[u'dec.deconv(data, lamb, num_iters=10, weights=1, k=0, k2=0)', u':module: PYME.Deconv.deccs_mc', u'', u'This is what you actually call to do the deconvolution.', u'parameters are:', u'', u'data - the raw data', u'lamb - the regularisation parameter', u'num_iters - number of iterations (note that the convergence is fast when', u'            compared to many algorithms - e.g Richardson-Lucy - and the', u'            default of 10 will usually already give a reasonable result)', u'', u'alpha - PSF phase - hacked in for variable phase 4Pi deconvolution, should', u'        really be refactored out into the dec_4pi classes.']:9: ERROR: Unexpected indentation.
[u'rldec.deconv(data, lamb, num_iters=10, weights=1, bg=0)', u':module: PYME.Deconv.richardsonLucy', u'', u'This is what you actually call to do the deconvolution.', u'parameters are:', u'', u'data - the raw data', u'lamb - the regularisation parameter', u'num_iters - number of iterations (note that the convergence is fast when', u'            compared to many algorithms - e.g Richardson-Lucy - and the', u'            default of 10 will usually already give a reasonable result)', u'', u'alpha - PSF phase - hacked in for variable phase 4Pi deconvolution, should', u'        really be refactored out into the dec_4pi classes.']:9: ERROR: Unexpected indentation.
[u'rldec.deconv(views, lamb, num_iters=10, weights=1, bg=0)', u':module: PYME.Deconv.richardsonLucyMV', u'', u'This is what you actually call to do the deconvolution.', u'parameters are:', u'', u'data - the raw data', u'lamb - the regularisation parameter', u'num_iters - number of iterations (note that the convergence is fast when', u'            compared to many algorithms - e.g Richardson-Lucy - and the', u'            default of 10 will usually already give a reasonable result)', u'', u'alpha - PSF phase - hacked in for variable phase 4Pi deconvolution, should', u'        really be refactored out into the dec_4pi classes.']:9: ERROR: Unexpected indentation.
[u'rldec.deconv(views, lamb, num_iters=10, weights=1, bg=0, vx=0)', u':module: PYME.Deconv.richardsonLucyMVM', u'', u'This is what you actually call to do the deconvolution.', u'parameters are:', u'', u'data - the raw data', u'lamb - the regularisation parameter', u'num_iters - number of iterations (note that the convergence is fast when', u'            compared to many algorithms - e.g Richardson-Lucy - and the', u'            default of 10 will usually already give a reasonable result)', u'', u'alpha - PSF phase - hacked in for variable phase 4Pi deconvolution, should', u'        really be refactored out into the dec_4pi classes.']:9: ERROR: Unexpected indentation.
/Users/david/python-microscopy/doc/api/Deconv/PYME.Deconv.tcluster.rst:4: WARNING: autodoc: failed to import module u'PYME.Deconv.tcluster'; the following exception was raised:
Traceback (most recent call last):
  File "/Users/david/anaconda/lib/python2.7/site-packages/Sphinx-1.3.1-py2.7.egg/sphinx/ext/autodoc.py", line 385, in import_object
    __import__(self.modname)
  File "/Users/david/python-microscopy/PYME/Deconv/tcluster.py", line 26, in <module>
    import scipy.cow.sync_cluster
ImportError: No module named sync_cluster
/Users/david/python-microscopy/doc/api/FileUtils/PYME.io.FileUtils.KdfSeqToHdf5.rst:4: WARNING: autodoc: failed to import module u'PYME.io.FileUtils.KdfSeqToHdf5'; the following exception was raised:
Traceback (most recent call last):
  File "/Users/david/anaconda/lib/python2.7/site-packages/Sphinx-1.3.1-py2.7.egg/sphinx/ext/autodoc.py", line 385, in import_object
    __import__(self.modname)
  File "/Users/david/python-microscopy/PYME.io.FileUtils/KdfSeqToHdf5.py", line 26, in <module>
    import read_kdf
  File "/Users/david/python-microscopy/PYME.io.FileUtils/read_kdf.py", line 28, in <module>
    from scipy.io.numpyio import *
ImportError: No module named numpyio
/Users/david/python-microscopy/doc/api/FileUtils/PYME.io.FileUtils.KdfStackToHdf5.rst:4: WARNING: autodoc: failed to import module u'PYME.io.FileUtils.KdfStackToHdf5'; the following exception was raised:
Traceback (most recent call last):
  File "/Users/david/anaconda/lib/python2.7/site-packages/Sphinx-1.3.1-py2.7.egg/sphinx/ext/autodoc.py", line 385, in import_object
    __import__(self.modname)
  File "/Users/david/python-microscopy/PYME.io.FileUtils/KdfStackToHdf5.py", line 26, in <module>
    import read_kdf
  File "/Users/david/python-microscopy/PYME.io.FileUtils/read_kdf.py", line 28, in <module>
    from scipy.io.numpyio import *
ImportError: No module named numpyio
/Users/david/python-microscopy/doc/api/FileUtils/PYME.io.FileUtils.RawToHdf5.rst:4: WARNING: autodoc: failed to import module u'PYME.io.FileUtils.RawToHdf5'; the following exception was raised:
Traceback (most recent call last):
  File "/Users/david/anaconda/lib/python2.7/site-packages/Sphinx-1.3.1-py2.7.egg/sphinx/ext/autodoc.py", line 385, in import_object
    __import__(self.modname)
  File "/Users/david/python-microscopy/PYME.io.FileUtils/RawToHdf5.py", line 26, in <module>
    import read_kdf
  File "/Users/david/python-microscopy/PYME.io.FileUtils/read_kdf.py", line 28, in <module>
    from scipy.io.numpyio import *
ImportError: No module named numpyio
/Users/david/python-microscopy/doc/api/FileUtils/PYME.io.FileUtils.abf.rst:14: WARNING: autodoc: failed to import module u'PYME.io.FileUtils.abf'; the following exception was raised:
Traceback (most recent call last):
  File "/Users/david/anaconda/lib/python2.7/site-packages/Sphinx-1.3.1-py2.7.egg/sphinx/ext/autodoc.py", line 385, in import_object
    __import__(self.modname)
  File "/Users/david/python-microscopy/PYME.io.FileUtils/abf/__init__.py", line 26, in <module>
    from abf import *
ImportError: No module named abf
/Users/david/python-microscopy/doc/api/FileUtils/PYME.io.FileUtils.abf.setup.rst:4: WARNING: autodoc: failed to import module u'PYME.io.FileUtils.abf.setup'; the following exception was raised:
Traceback (most recent call last):
  File "/Users/david/anaconda/lib/python2.7/site-packages/Sphinx-1.3.1-py2.7.egg/sphinx/ext/autodoc.py", line 385, in import_object
    __import__(self.modname)
  File "/Users/david/python-microscopy/PYME.io.FileUtils/abf/__init__.py", line 26, in <module>
    from abf import *
ImportError: No module named abf
/Users/david/python-microscopy/doc/api/FileUtils/PYME.io.FileUtils.batchConvertKdf.rst:4: WARNING: autodoc: failed to import module u'PYME.io.FileUtils.batchConvertKdf'; the following exception was raised:
Traceback (most recent call last):
  File "/Users/david/anaconda/lib/python2.7/site-packages/Sphinx-1.3.1-py2.7.egg/sphinx/ext/autodoc.py", line 385, in import_object
    __import__(self.modname)
  File "/Users/david/python-microscopy/PYME.io.FileUtils/batchConvertKdf.py", line 27, in <module>
    import KdfStackToHdf5
  File "/Users/david/python-microscopy/PYME.io.FileUtils/KdfStackToHdf5.py", line 26, in <module>
    import read_kdf
  File "/Users/david/python-microscopy/PYME.io.FileUtils/read_kdf.py", line 28, in <module>
    from scipy.io.numpyio import *
ImportError: No module named numpyio
/Users/david/python-microscopy/doc/api/FileUtils/PYME.io.FileUtils.compHdf.rst:4: WARNING: autodoc: failed to import module u'PYME.io.FileUtils.compHdf'; the following exception was raised:
Traceback (most recent call last):
  File "/Users/david/anaconda/lib/python2.7/site-packages/Sphinx-1.3.1-py2.7.egg/sphinx/ext/autodoc.py", line 385, in import_object
    __import__(self.modname)
  File "/Users/david/python-microscopy/PYME.io.FileUtils/compHdf.py", line 26, in <module>
    if not (len(sys.argv) in [2,3]):
NameError: name 'sys' is not defined
/Users/david/python-microscopy/doc/api/FileUtils/PYME.io.FileUtils.h5-thumbnailer.rst:4: WARNING: invalid signature for automodule (u'PYME.io.FileUtils.h5-thumbnailer')
/Users/david/python-microscopy/doc/api/FileUtils/PYME.io.FileUtils.h5-thumbnailer.rst:4: WARNING: don't know which module to import for autodocumenting u'PYME.io.FileUtils.h5-thumbnailer' (try placing a "module" or "currentmodule" directive in the document, or giving an explicit module name)
/Users/david/python-microscopy/doc/api/FileUtils/PYME.io.FileUtils.h5ToTiffSeries.rst:4: WARNING: autodoc: failed to import module u'PYME.io.FileUtils.h5ToTiffSeries'; the following exception was raised:
Traceback (most recent call last):
  File "/Users/david/anaconda/lib/python2.7/site-packages/Sphinx-1.3.1-py2.7.egg/sphinx/ext/autodoc.py", line 385, in import_object
    __import__(self.modname)
  File "/Users/david/python-microscopy/PYME.io.FileUtils/h5ToTiffSeries.py", line 30, in <module>
    raise RuntimeError('Usage: h5ToTiffSeries infile outdir')
RuntimeError: Usage: h5ToTiffSeries infile outdir
/Users/david/python-microscopy/doc/api/FileUtils/PYME.io.FileUtils.h5r-thumbnailer.rst:4: WARNING: invalid signature for automodule (u'PYME.io.FileUtils.h5r-thumbnailer')
/Users/david/python-microscopy/doc/api/FileUtils/PYME.io.FileUtils.h5r-thumbnailer.rst:4: WARNING: don't know which module to import for autodocumenting u'PYME.io.FileUtils.h5r-thumbnailer' (try placing a "module" or "currentmodule" directive in the document, or giving an explicit module name)
/Users/david/python-microscopy/doc/api/FileUtils/PYME.io.FileUtils.h5rFormatDef.rst:4: WARNING: autodoc: failed to import module u'PYME.io.FileUtils.h5rFormatDef'; the following exception was raised:
Traceback (most recent call last):
  File "/Users/david/anaconda/lib/python2.7/site-packages/Sphinx-1.3.1-py2.7.egg/sphinx/ext/autodoc.py", line 385, in import_object
    __import__(self.modname)
  File "/Users/david/python-microscopy/PYME.io.FileUtils/h5rFormatDef.py", line 29, in <module>
    h5ResultsFile = tables.openFile(resultsFilename, 'w')
NameError: name 'resultsFilename' is not defined
/Users/david/python-microscopy/doc/api/FileUtils/PYME.io.FileUtils.kdf-thumbnailer.rst:4: WARNING: invalid signature for automodule (u'PYME.io.FileUtils.kdf-thumbnailer')
/Users/david/python-microscopy/doc/api/FileUtils/PYME.io.FileUtils.kdf-thumbnailer.rst:4: WARNING: don't know which module to import for autodocumenting u'PYME.io.FileUtils.kdf-thumbnailer' (try placing a "module" or "currentmodule" directive in the document, or giving an explicit module name)
/Users/david/python-microscopy/doc/api/FileUtils/PYME.io.FileUtils.kdfToFloat32Tiff.rst:4: WARNING: autodoc: failed to import module u'PYME.io.FileUtils.kdfToFloat32Tiff'; the following exception was raised:
Traceback (most recent call last):
  File "/Users/david/anaconda/lib/python2.7/site-packages/Sphinx-1.3.1-py2.7.egg/sphinx/ext/autodoc.py", line 385, in import_object
    __import__(self.modname)
  File "/Users/david/python-microscopy/PYME.io.FileUtils/kdfToFloat32Tiff.py", line 25, in <module>
    import read_kdf
  File "/Users/david/python-microscopy/PYME.io.FileUtils/read_kdf.py", line 28, in <module>
    from scipy.io.numpyio import *
ImportError: No module named numpyio
/Users/david/python-microscopy/doc/api/FileUtils/PYME.io.FileUtils.kdfToImage.rst:4: WARNING: autodoc: failed to import module u'PYME.io.FileUtils.kdfToImage'; the following exception was raised:
Traceback (most recent call last):
  File "/Users/david/anaconda/lib/python2.7/site-packages/Sphinx-1.3.1-py2.7.egg/sphinx/ext/autodoc.py", line 385, in import_object
    __import__(self.modname)
  File "/Users/david/python-microscopy/PYME.io.FileUtils/kdfToImage.py", line 25, in <module>
    import read_kdf
  File "/Users/david/python-microscopy/PYME.io.FileUtils/read_kdf.py", line 28, in <module>
    from scipy.io.numpyio import *
ImportError: No module named numpyio
/Users/david/python-microscopy/doc/api/FileUtils/PYME.io.FileUtils.read_kdf.rst:4: WARNING: autodoc: failed to import module u'PYME.io.FileUtils.read_kdf'; the following exception was raised:
Traceback (most recent call last):
  File "/Users/david/anaconda/lib/python2.7/site-packages/Sphinx-1.3.1-py2.7.egg/sphinx/ext/autodoc.py", line 385, in import_object
    __import__(self.modname)
  File "/Users/david/python-microscopy/PYME.io.FileUtils/read_kdf.py", line 28, in <module>
    from scipy.io.numpyio import *
ImportError: No module named numpyio
/Users/david/python-microscopy/doc/api/FileUtils/PYME.io.FileUtils.sf-thumbnailer.rst:4: WARNING: invalid signature for automodule (u'PYME.io.FileUtils.sf-thumbnailer')
/Users/david/python-microscopy/doc/api/FileUtils/PYME.io.FileUtils.sf-thumbnailer.rst:4: WARNING: don't know which module to import for autodocumenting u'PYME.io.FileUtils.sf-thumbnailer' (try placing a "module" or "currentmodule" directive in the document, or giving an explicit module name)
/Users/david/python-microscopy/doc/api/FileUtils/PYME.io.FileUtils.thumbnailDatabase.rst:4: WARNING: autodoc: failed to import module u'PYME.io.FileUtils.thumbnailDatabase'; the following exception was raised:
Traceback (most recent call last):
  File "/Users/david/anaconda/lib/python2.7/site-packages/Sphinx-1.3.1-py2.7.egg/sphinx/ext/autodoc.py", line 385, in import_object
    __import__(self.modname)
  File "/Users/david/python-microscopy/PYME.io.FileUtils/thumbnailDatabase.py", line 44, in <module>
    thumbDB = sqlite3.connect('/srv/PYME/PYMEThumbnails.db', detect_types=sqlite3.PARSE_DECLTYPES|sqlite3.PARSE_COLNAMES)
OperationalError: unable to open database file
/Users/david/python-microscopy/doc/api/FileUtils/PYME.io.FileUtils.write_kdf.rst:4: WARNING: autodoc: failed to import module u'PYME.io.FileUtils.write_kdf'; the following exception was raised:
Traceback (most recent call last):
  File "/Users/david/anaconda/lib/python2.7/site-packages/Sphinx-1.3.1-py2.7.egg/sphinx/ext/autodoc.py", line 385, in import_object
    __import__(self.modname)
  File "/Users/david/python-microscopy/PYME.io.FileUtils/write_kdf.py", line 33, in <module>
    if int(scipy.version.version.split('.')[1]) > 5:
TypeError: 'Mock' object does not support indexing
/Users/david/python-microscopy/doc/api/PYME.rst:7: WARNING: toctree contains reference to nonexisting document u'api/PYME.JythonDummies'
/Users/david/python-microscopy/doc/api/PYME.rst:7: WARNING: toctree contains reference to nonexisting document u'api/PYME.SampleDB2'
/Users/david/python-microscopy/doc/api/PYME.rst:7: WARNING: toctree contains reference to nonexisting document u'api/PYME.aniso'
/Users/david/python-microscopy/doc/api/PYME.rst:7: WARNING: toctree contains reference to nonexisting document u'api/PYME.bcl'
/Users/david/python-microscopy/doc/api/PYME.rst:7: WARNING: toctree contains reference to nonexisting document u'api/PYME.cSMI'
/Users/david/python-microscopy/doc/api/PYME.rst:7: WARNING: toctree contains reference to nonexisting document u'api/PYME.cpmath'
/Users/david/python-microscopy/doc/api/PYME.rst:7: WARNING: toctree contains reference to nonexisting document u'api/PYME.dataBrowser'
/Users/david/python-microscopy/doc/api/PYME.rst:7: WARNING: toctree contains reference to nonexisting document u'api/PYME.gohlke'
/Users/david/python-microscopy/doc/api/PYME.rst:7: WARNING: toctree contains reference to nonexisting document u'api/PYME.pad'
/Users/david/python-microscopy/doc/api/PYME.rst:34: WARNING: toctree contains reference to nonexisting document u'api/PYME.install_dependencies'
/Users/david/python-microscopy/doc/api/PYME.rst:34: WARNING: toctree contains reference to nonexisting document u'api/PYME.setup'
/Users/david/python-microscopy/doc/api/PYME.rst:34: WARNING: toctree contains reference to nonexisting document u'api/PYME.setup_exe'
/Users/david/python-microscopy/doc/api/PYME.PSFGen.fourier.rst:4: WARNING: autodoc: failed to import module u'PYME.PSFGen.fourier'; the following exception was raised:
Traceback (most recent call last):
  File "/Users/david/anaconda/lib/python2.7/site-packages/Sphinx-1.3.1-py2.7.egg/sphinx/ext/autodoc.py", line 385, in import_object
    __import__(self.modname)
  File "/Users/david/python-microscopy/PYME/PSFGen/fourier.py", line 25, in <module>
    k = 2*pi/488 #k at 488nm
NameError: name 'pi' is not defined
/Users/david/python-microscopy/doc/api/PYME.PSFGen.fourierHNA.rst:4: WARNING: autodoc: failed to import module u'PYME.PSFGen.fourierHNA'; the following exception was raised:
Traceback (most recent call last):
  File "/Users/david/anaconda/lib/python2.7/site-packages/Sphinx-1.3.1-py2.7.egg/sphinx/ext/autodoc.py", line 385, in import_object
    __import__(self.modname)
  File "/Users/david/python-microscopy/PYME/PSFGen/fourierHNA.py", line 37, in <module>
    k = 2*pi*n/lamb #k at 488nm
NameError: name 'pi' is not defined
/Users/david/python-microscopy/doc/api/PYME.PSFGen.genCRBcurves.rst:4: WARNING: autodoc: failed to import module u'PYME.PSFGen.genCRBcurves'; the following exception was raised:
Traceback (most recent call last):
  File "/Users/david/anaconda/lib/python2.7/site-packages/Sphinx-1.3.1-py2.7.egg/sphinx/ext/autodoc.py", line 385, in import_object
    __import__(self.modname)
  File "/Users/david/python-microscopy/PYME/PSFGen/genCRBcurves.py", line 25, in <module>
    import fourierHNA
  File "/Users/david/python-microscopy/PYME/PSFGen/fourierHNA.py", line 37, in <module>
    k = 2*pi*n/lamb #k at 488nm
NameError: name 'pi' is not defined
/Users/david/python-microscopy/doc/api/ParallelTasks/PYME.ParallelTasks.DSTaskQueue.rst:4: WARNING: autodoc: failed to import module u'PYME.ParallelTasks.DSTaskQueue'; the following exception was raised:
Traceback (most recent call last):
  File "/Users/david/anaconda/lib/python2.7/site-packages/Sphinx-1.3.1-py2.7.egg/sphinx/ext/autodoc.py", line 385, in import_object
    __import__(self.modname)
  File "/Users/david/python-microscopy/PYME/ParallelTasks/DSTaskQueue.py", line 10, in <module>
    from .HDFTaskQueue import HDFResultsTaskQueue, doNix, popZero, CHUNKSIZE, MAXCHUNKSIZE, fitTask
  File "/Users/david/python-microscopy/PYME/ParallelTasks/HDFTaskQueue.py", line 26, in <module>
    from PYME.Analysis.remFitBuf import fitTask
  File "/Users/david/python-microscopy/PYME/Analysis/remFitBuf.py", line 25, in <module>
    from PYME.Analysis import ofind
  File "/Users/david/python-microscopy/PYME/Analysis/ofind.py", line 56, in <module>
    weightsLowpass = calc_gauss_weights(filtRadLowpass)
  File "/Users/david/python-microscopy/PYME/Analysis/ofind.py", line 39, in calc_gauss_weights
    weights[lw] = 1.0
TypeError: 'Mock' object does not support item assignment
/Users/david/python-microscopy/doc/api/ParallelTasks/PYME.ParallelTasks.HDFTaskQueue.rst:4: WARNING: autodoc: failed to import module u'PYME.ParallelTasks.HDFTaskQueue'; the following exception was raised:
Traceback (most recent call last):
  File "/Users/david/anaconda/lib/python2.7/site-packages/Sphinx-1.3.1-py2.7.egg/sphinx/ext/autodoc.py", line 385, in import_object
    __import__(self.modname)
  File "/Users/david/python-microscopy/PYME/ParallelTasks/HDFTaskQueue.py", line 26, in <module>
    from PYME.Analysis.remFitBuf import fitTask
  File "/Users/david/python-microscopy/PYME/Analysis/remFitBuf.py", line 25, in <module>
    from PYME.Analysis import ofind
  File "/Users/david/python-microscopy/PYME/Analysis/ofind.py", line 56, in <module>
    weightsLowpass = calc_gauss_weights(filtRadLowpass)
  File "/Users/david/python-microscopy/PYME/Analysis/ofind.py", line 39, in calc_gauss_weights
    weights[lw] = 1.0
TypeError: 'Mock' object does not support item assignment
/Users/david/python-microscopy/doc/api/ParallelTasks/PYME.ParallelTasks.hdfWatcher.rst:4: WARNING: autodoc: failed to import module u'PYME.ParallelTasks.hdfWatcher'; the following exception was raised:
Traceback (most recent call last):
  File "/Users/david/anaconda/lib/python2.7/site-packages/Sphinx-1.3.1-py2.7.egg/sphinx/ext/autodoc.py", line 385, in import_object
    __import__(self.modname)
  File "/Users/david/python-microscopy/PYME/ParallelTasks/hdfWatcher.py", line 27, in <module>
    import remFitHDF
ImportError: No module named remFitHDF
/Users/david/python-microscopy/doc/api/ParallelTasks/PYME.ParallelTasks.httpSpoolTarget.rst:4: WARNING: autodoc: failed to import module u'PYME.ParallelTasks.httpSpoolTarget'; the following exception was raised:
Traceback (most recent call last):
  File "/Users/david/anaconda/lib/python2.7/site-packages/Sphinx-1.3.1-py2.7.egg/sphinx/ext/autodoc.py", line 385, in import_object
    __import__(self.modname)
  File "/Users/david/python-microscopy/PYME/ParallelTasks/httpSpoolTarget.py", line 6, in <module>
    from PYME.ParallelTasks import HDFTaskQueue
  File "/Users/david/python-microscopy/PYME/ParallelTasks/HDFTaskQueue.py", line 26, in <module>
    from PYME.Analysis.remFitBuf import fitTask
  File "/Users/david/python-microscopy/PYME/Analysis/remFitBuf.py", line 25, in <module>
    from PYME.Analysis import ofind
  File "/Users/david/python-microscopy/PYME/Analysis/ofind.py", line 56, in <module>
    weightsLowpass = calc_gauss_weights(filtRadLowpass)
  File "/Users/david/python-microscopy/PYME/Analysis/ofind.py", line 39, in calc_gauss_weights
    weights[lw] = 1.0
TypeError: 'Mock' object does not support item assignment
/Users/david/python-microscopy/doc/api/ParallelTasks/PYME.ParallelTasks.httpSpoolTargetSpoof.rst:4: WARNING: autodoc: failed to import module u'PYME.ParallelTasks.httpSpoolTargetSpoof'; the following exception was raised:
Traceback (most recent call last):
  File "/Users/david/anaconda/lib/python2.7/site-packages/Sphinx-1.3.1-py2.7.egg/sphinx/ext/autodoc.py", line 385, in import_object
    __import__(self.modname)
  File "/Users/david/python-microscopy/PYME/ParallelTasks/httpSpoolTargetSpoof.py", line 6, in <module>
    from PYME.ParallelTasks import HDFTaskQueue
  File "/Users/david/python-microscopy/PYME/ParallelTasks/HDFTaskQueue.py", line 26, in <module>
    from PYME.Analysis.remFitBuf import fitTask
  File "/Users/david/python-microscopy/PYME/Analysis/remFitBuf.py", line 25, in <module>
    from PYME.Analysis import ofind
  File "/Users/david/python-microscopy/PYME/Analysis/ofind.py", line 56, in <module>
    weightsLowpass = calc_gauss_weights(filtRadLowpass)
  File "/Users/david/python-microscopy/PYME/Analysis/ofind.py", line 39, in calc_gauss_weights
    weights[lw] = 1.0
TypeError: 'Mock' object does not support item assignment
/Users/david/python-microscopy/doc/api/ParallelTasks/PYME.ParallelTasks.launchOnlyWorkers.rst:4: WARNING: autodoc: failed to import module u'PYME.ParallelTasks.launchOnlyWorkers'; the following exception was raised:
Traceback (most recent call last):
  File "/Users/david/anaconda/lib/python2.7/site-packages/Sphinx-1.3.1-py2.7.egg/sphinx/ext/autodoc.py", line 385, in import_object
    __import__(self.modname)
  File "/Users/david/python-microscopy/PYME/ParallelTasks/launchOnlyWorkers.py", line 71, in <module>
    numProcessors = int(sys.argv[1])
ValueError: invalid literal for int() with base 10: '-b'
/Users/david/python-microscopy/doc/api/ParallelTasks/PYME.ParallelTasks.taskServerMP.rst:4: WARNING: autodoc: failed to import module u'PYME.ParallelTasks.taskServerMP'; the following exception was raised:
Traceback (most recent call last):
  File "/Users/david/anaconda/lib/python2.7/site-packages/Sphinx-1.3.1-py2.7.egg/sphinx/ext/autodoc.py", line 385, in import_object
    __import__(self.modname)
  File "/Users/david/python-microscopy/PYME/ParallelTasks/taskServerMP.py", line 32, in <module>
    from HDFTaskQueue import *
  File "/Users/david/python-microscopy/PYME/ParallelTasks/HDFTaskQueue.py", line 26, in <module>
    from PYME.Analysis.remFitBuf import fitTask
  File "/Users/david/python-microscopy/PYME/Analysis/remFitBuf.py", line 25, in <module>
    from PYME.Analysis import ofind
  File "/Users/david/python-microscopy/PYME/Analysis/ofind.py", line 56, in <module>
    weightsLowpass = calc_gauss_weights(filtRadLowpass)
  File "/Users/david/python-microscopy/PYME/Analysis/ofind.py", line 39, in calc_gauss_weights
    weights[lw] = 1.0
TypeError: 'Mock' object does not support item assignment
/Users/david/python-microscopy/doc/api/ParallelTasks/PYME.ParallelTasks.taskServerZC.rst:4: WARNING: autodoc: failed to import module u'PYME.ParallelTasks.taskServerZC'; the following exception was raised:
Traceback (most recent call last):
  File "/Users/david/anaconda/lib/python2.7/site-packages/Sphinx-1.3.1-py2.7.egg/sphinx/ext/autodoc.py", line 385, in import_object
    __import__(self.modname)
  File "/Users/david/python-microscopy/PYME/ParallelTasks/taskServerZC.py", line 32, in <module>
    from HDFTaskQueue import *
  File "/Users/david/python-microscopy/PYME/ParallelTasks/HDFTaskQueue.py", line 26, in <module>
    from PYME.Analysis.remFitBuf import fitTask
  File "/Users/david/python-microscopy/PYME/Analysis/remFitBuf.py", line 25, in <module>
    from PYME.Analysis import ofind
  File "/Users/david/python-microscopy/PYME/Analysis/ofind.py", line 56, in <module>
    weightsLowpass = calc_gauss_weights(filtRadLowpass)
  File "/Users/david/python-microscopy/PYME/Analysis/ofind.py", line 39, in calc_gauss_weights
    weights[lw] = 1.0
TypeError: 'Mock' object does not support item assignment
/Users/david/python-microscopy/doc/api/ParallelTasks/PYME.ParallelTasks.taskWorkerMP.rst:4: WARNING: autodoc: failed to import module u'PYME.ParallelTasks.taskWorkerMP'; the following exception was raised:
Traceback (most recent call last):
  File "/Users/david/anaconda/lib/python2.7/site-packages/Sphinx-1.3.1-py2.7.egg/sphinx/ext/autodoc.py", line 385, in import_object
    __import__(self.modname)
  File "/Users/david/python-microscopy/PYME/ParallelTasks/taskWorkerMP.py", line 52, in <module>
    ns=Pyro.naming.NameServerLocator().getNS()
  File "/Users/david/anaconda/lib/python2.7/site-packages/Pyro/naming.py", line 176, in getNS
    reply = self.sendSysCommand(NS_SYSCMD_LOCATION,host,port,trace,1,bcaddr)
  File "/Users/david/anaconda/lib/python2.7/site-packages/Pyro/naming.py", line 76, in sendSysCommand
    raise Pyro.errors.NamingError("could not find NameServer")
NamingError: could not find NameServer
[u'get_profile_stats()', u':module: PYME.mProfile.tProfile', u'', u'', u'', u'returns dict[function_tuple] -> stats_tuple', u'where', u'  function_tuple = (function_name, filename, lineno)', u'  stats_tuple = (call_cnt, real_time, cpu_time)']:5: ERROR: Unexpected indentation.
/Users/david/python-microscopy/PYME/misc/TextCtrlAutoComplete.py:docstring of PYME.misc.TextCtrlAutoComplete:3: ERROR: Unexpected indentation.
/Users/david/python-microscopy/PYME/misc/TextCtrlAutoComplete.py:docstring of PYME.misc.TextCtrlAutoComplete:5: WARNING: Block quote ends without a blank line; unexpected unindent.
/Users/david/python-microscopy/doc/api/misc/PYME.misc.VolProj.rst:4: WARNING: autodoc: failed to import module u'PYME.misc.VolProj'; the following exception was raised:
Traceback (most recent call last):
  File "/Users/david/anaconda/lib/python2.7/site-packages/Sphinx-1.3.1-py2.7.egg/sphinx/ext/autodoc.py", line 385, in import_object
    __import__(self.modname)
  File "/Users/david/python-microscopy/PYME/misc/VolProj.py", line 23, in <module>
    from enthought.mayavi import mlab
ImportError: No module named enthought.mayavi
/Users/david/python-microscopy/doc/api/misc/PYME.misc.calenderApi.rst:4: WARNING: autodoc: failed to import module u'PYME.misc.calenderApi'; the following exception was raised:
Traceback (most recent call last):
  File "/Users/david/anaconda/lib/python2.7/site-packages/Sphinx-1.3.1-py2.7.egg/sphinx/ext/autodoc.py", line 385, in import_object
    __import__(self.modname)
  File "/Users/david/python-microscopy/PYME/misc/calenderApi.py", line 25, in <module>
    import gflags
ImportError: No module named gflags
[u"congrid(a, newdims, method='linear', centre=False, minusone=False)", u':module: PYME.misc.congrid', u'', u'', u'', u'Arbitrary resampling of source array to new dimension sizes.', u'Currently only supports maintaining the same number of dimensions.', u'To use 1-D arrays, first promote them to shape (x,1).', u'', u'Uses the same parameters and creates the same co-ordinate lookup points', u"as IDL''s congrid routine, which apparently originally came from a VAX/VMS", u'routine of the same name.', u'', u'method:', u'neighbour - closest value from original data', u'nearest and linear - uses n x 1-D interpolations using', u'                     scipy.interpolate.interp1d', u'(see Numerical Recipes for validity of use of n 1-D interpolations)', u'spline - uses ndimage.map_coordinates', u'', u'centre:', u'True - interpolation points are at the centres of the bins', u'False - points are at the front edge of the bin', u'', u'minusone:', u'For example- inarray.shape = (i,j) & new dimensions = (x,y)', u'False - inarray is resampled by factors of (i/x) * (j/y)', u'True - inarray is resampled by(i-1)/(x-1) * (j-1)/(y-1)', u'This prevents extrapolation one element beyond bounds of input array.']:14: ERROR: Unexpected indentation.
/Users/david/python-microscopy/PYME/misc/congrid.py:docstring of PYME.misc.congrid.congrid:17: WARNING: Block quote ends without a blank line; unexpected unindent.
/Users/david/python-microscopy/doc/api/misc/PYME.misc.coverslipGeometries.rst:4: WARNING: autodoc: failed to import module u'PYME.misc.coverslipGeometries'; the following exception was raised:
Traceback (most recent call last):
  File "/Users/david/anaconda/lib/python2.7/site-packages/Sphinx-1.3.1-py2.7.egg/sphinx/ext/autodoc.py", line 385, in import_object
    __import__(self.modname)
  File "/Users/david/python-microscopy/PYME/misc/coverslipGeometries.py", line 23, in <module>
    from scipy.optimize import fmin
ImportError: No module named optimize
/Users/david/python-microscopy/doc/api/misc/PYME.misc.cython_numpy_monkey.rst:4: WARNING: autodoc: failed to import module u'PYME.misc.cython_numpy_monkey'; the following exception was raised:
Traceback (most recent call last):
  File "/Users/david/anaconda/lib/python2.7/site-packages/Sphinx-1.3.1-py2.7.egg/sphinx/ext/autodoc.py", line 385, in import_object
    __import__(self.modname)
  File "/Users/david/python-microscopy/PYME/misc/cython_numpy_monkey.py", line 6, in <module>
    from numpy.distutils.misc_util import appendpath
ImportError: No module named distutils.misc_util
/Users/david/python-microscopy/doc/api/misc/PYME.misc.extraCMaps.rst:4: WARNING: autodoc: failed to import module u'PYME.misc.extraCMaps'; the following exception was raised:
Traceback (most recent call last):
  File "/Users/david/anaconda/lib/python2.7/site-packages/Sphinx-1.3.1-py2.7.egg/sphinx/ext/autodoc.py", line 385, in import_object
    __import__(self.modname)
  File "/Users/david/python-microscopy/PYME/misc/extraCMaps.py", line 58, in <module>
    pylab.cm.cmapnames += ncmapnames
TypeError: unsupported operand type(s) for +=: 'Mock' and 'list'
/Users/david/python-microscopy/PYME/misc/findCycles.py:docstring of PYME.misc.findCycles.print_cycles:8: WARNING: Definition list ends without a blank line; unexpected unindent.
[u"print_cycles(objects, outstream=<open file '<stdout>', mode 'w'>, show_progress=False)", u':module: PYME.misc.findCycles', u'', u'', u'', u'objects:       A list of objects to find cycles in.  It is often useful', u'               to pass in gc.garbage to find the cycles that are', u'               preventing some objects from being garbage collected.', u'outstream:     The stream for output.', u'show_progress: If True, print the number of objects reached as they are', u'               found.']:8: ERROR: Unexpected indentation.
/Users/david/python-microscopy/doc/api/misc/PYME.misc.hillcurve.rst:4: WARNING: autodoc: failed to import module u'PYME.misc.hillcurve'; the following exception was raised:
Traceback (most recent call last):
  File "/Users/david/anaconda/lib/python2.7/site-packages/Sphinx-1.3.1-py2.7.egg/sphinx/ext/autodoc.py", line 385, in import_object
    __import__(self.modname)
  File "/Users/david/python-microscopy/PYME/misc/hillcurve.py", line 26, in <module>
    from PYME.Analysis._fithelpers import *
  File "/Users/david/python-microscopy/PYME/Analysis/_fithelpers.py", line 25, in <module>
    import scipy.optimize as optimize
ImportError: No module named optimize
/Users/david/python-microscopy/doc/api/misc/PYME.misc.kdFit.rst:4: WARNING: autodoc: failed to import module u'PYME.misc.kdFit'; the following exception was raised:
Traceback (most recent call last):
  File "/Users/david/anaconda/lib/python2.7/site-packages/Sphinx-1.3.1-py2.7.egg/sphinx/ext/autodoc.py", line 385, in import_object
    __import__(self.modname)
  File "/Users/david/python-microscopy/PYME/misc/kdFit.py", line 25, in <module>
    from PYME.Analysis._fithelpers import *
  File "/Users/david/python-microscopy/PYME/Analysis/_fithelpers.py", line 25, in <module>
    import scipy.optimize as optimize
ImportError: No module named optimize
/Users/david/python-microscopy/doc/api/misc/PYME.misc.memmap.rst:4: WARNING: autodoc: failed to import module u'PYME.misc.memmap'; the following exception was raised:
Traceback (most recent call last):
  File "/Users/david/anaconda/lib/python2.7/site-packages/Sphinx-1.3.1-py2.7.egg/sphinx/ext/autodoc.py", line 385, in import_object
    __import__(self.modname)
  File "/Users/david/python-microscopy/PYME/misc/memmap.py", line 25, in <module>
    from guppy import hpy
ImportError: No module named guppy
/Users/david/python-microscopy/doc/api/misc/PYME.misc.optics.rst:4: WARNING: autodoc: failed to import module u'PYME.misc.optics'; the following exception was raised:
Traceback (most recent call last):
  File "/Users/david/anaconda/lib/python2.7/site-packages/Sphinx-1.3.1-py2.7.egg/sphinx/ext/autodoc.py", line 385, in import_object
    __import__(self.modname)
  File "/Users/david/python-microscopy/PYME/misc/optics.py", line 46, in <module>
    import scipy.spatial.distance as H
ImportError: No module named distance
/Users/david/python-microscopy/doc/api/misc/PYME.misc.tempDB.rst:4: WARNING: autodoc: failed to import module u'PYME.misc.tempDB'; the following exception was raised:
Traceback (most recent call last):
  File "/Users/david/anaconda/lib/python2.7/site-packages/Sphinx-1.3.1-py2.7.egg/sphinx/ext/autodoc.py", line 385, in import_object
    __import__(self.modname)
  File "/Users/david/python-microscopy/PYME/misc/tempDB.py", line 23, in <module>
    import MySQLdb
ImportError: No module named MySQLdb
/Users/david/python-microscopy/doc/api/misc/PYME.misc.tempLogger.rst:4: WARNING: autodoc: failed to import module u'PYME.misc.tempLogger'; the following exception was raised:
Traceback (most recent call last):
  File "/Users/david/anaconda/lib/python2.7/site-packages/Sphinx-1.3.1-py2.7.egg/sphinx/ext/autodoc.py", line 385, in import_object
    __import__(self.modname)
  File "/Users/david/python-microscopy/PYME/misc/tempLogger.py", line 26, in <module>
    dd = getDDClient()
  File "/Users/david/python-microscopy/PYME/Acquire/Hardware/DigiData/DigiDataClient.py", line 30, in getDDClient
    return Pyro.core.getProxyForURI('PYRONAME://DigiData')
  File "/Users/david/anaconda/lib/python2.7/site-packages/Pyro/core.py", line 368, in getProxyForURI
    return DynamicProxy(URI)
  File "/Users/david/anaconda/lib/python2.7/site-packages/Pyro/core.py", line 387, in __init__
    URI=processStringURI(URI)
  File "/Users/david/anaconda/lib/python2.7/site-packages/Pyro/core.py", line 335, in processStringURI
    NS=loc.getNS(host=hostname,port=port)
  File "/Users/david/anaconda/lib/python2.7/site-packages/Pyro/naming.py", line 176, in getNS
    reply = self.sendSysCommand(NS_SYSCMD_LOCATION,host,port,trace,1,bcaddr)
  File "/Users/david/anaconda/lib/python2.7/site-packages/Pyro/naming.py", line 76, in sendSysCommand
    raise Pyro.errors.NamingError("could not find NameServer")
NamingError: could not find NameServer
/Users/david/python-microscopy/doc/api/misc/PYME.misc.tempLoggerDB.rst:4: WARNING: autodoc: failed to import module u'PYME.misc.tempLoggerDB'; the following exception was raised:
Traceback (most recent call last):
  File "/Users/david/anaconda/lib/python2.7/site-packages/Sphinx-1.3.1-py2.7.egg/sphinx/ext/autodoc.py", line 385, in import_object
    __import__(self.modname)
  File "/Users/david/python-microscopy/PYME/misc/tempLoggerDB.py", line 26, in <module>
    import tempDB
  File "/Users/david/python-microscopy/PYME/misc/tempDB.py", line 23, in <module>
    import MySQLdb
ImportError: No module named MySQLdb
/Users/david/python-microscopy/doc/api/misc/PYME.misc.tempMonitor.rst:4: WARNING: autodoc: failed to import module u'PYME.misc.tempMonitor'; the following exception was raised:
Traceback (most recent call last):
  File "/Users/david/anaconda/lib/python2.7/site-packages/Sphinx-1.3.1-py2.7.egg/sphinx/ext/autodoc.py", line 385, in import_object
    __import__(self.modname)
  File "/Users/david/python-microscopy/PYME/misc/tempMonitor.py", line 26, in <module>
    dd = getDDClient()
  File "/Users/david/python-microscopy/PYME/Acquire/Hardware/DigiData/DigiDataClient.py", line 30, in getDDClient
    return Pyro.core.getProxyForURI('PYRONAME://DigiData')
  File "/Users/david/anaconda/lib/python2.7/site-packages/Pyro/core.py", line 368, in getProxyForURI
    return DynamicProxy(URI)
  File "/Users/david/anaconda/lib/python2.7/site-packages/Pyro/core.py", line 387, in __init__
    URI=processStringURI(URI)
  File "/Users/david/anaconda/lib/python2.7/site-packages/Pyro/core.py", line 335, in processStringURI
    NS=loc.getNS(host=hostname,port=port)
  File "/Users/david/anaconda/lib/python2.7/site-packages/Pyro/naming.py", line 176, in getNS
    reply = self.sendSysCommand(NS_SYSCMD_LOCATION,host,port,trace,1,bcaddr)
  File "/Users/david/anaconda/lib/python2.7/site-packages/Pyro/naming.py", line 76, in sendSysCommand
    raise Pyro.errors.NamingError("could not find NameServer")
NamingError: could not find NameServer
/Users/david/python-microscopy/doc/api/modules.rst:2: WARNING: Explicit markup ends without a blank line; unexpected unindent.
/Users/david/python-microscopy/doc/api/modules.rst:4: WARNING: toctree contains reference to nonexisting document u'api/setup'
/Users/david/python-microscopy/doc/api/shmarray/PYME.shmarray.shmTest.rst:4: WARNING: autodoc: failed to import module u'PYME.shmarray.shmTest'; the following exception was raised:
Traceback (most recent call last):
  File "/Users/david/anaconda/lib/python2.7/site-packages/Sphinx-1.3.1-py2.7.egg/sphinx/ext/autodoc.py", line 385, in import_object
    __import__(self.modname)
  File "/Users/david/python-microscopy/PYME/shmarray/shmTest.py", line 30, in <module>
    data = shmarray.zeros(100)
  File "/Users/david/python-microscopy/PYME/shmarray/shmarray.py", line 114, in zeros
    sa = create(shape, dtype='d', order=order)
  File "/Users/david/python-microscopy/PYME/shmarray/shmarray.py", line 102, in create
    N *= dtype.itemsize
TypeError: unsupported operand type(s) for *=: 'Mock' and 'Mock'
/Users/david/python-microscopy/doc/index.rst:7: WARNING: Explicit markup ends without a blank line; unexpected unindent.
/Users/david/python-microscopy/doc/Technical.rst:: WARNING: document isn't included in any toctree
/Users/david/python-microscopy/doc/api/Acquire/PYME.Acquire.setup.rst:: WARNING: document isn't included in any toctree
/Users/david/python-microscopy/doc/api/modules.rst:: WARNING: document isn't included in any toctree
/Users/david/python-microscopy/doc/dh5view.rst:: WARNING: document isn't included in any toctree
/Users/david/python-microscopy/doc/VisGUI.rst:11: WARNING: undefined label: installation (if the link has no caption the label must precede a section header)
/Users/david/python-microscopy/doc/VisGUI.rst:60: WARNING: undefined label: the filter (if the link has no caption the label must precede a section header)
/Users/david/python-microscopy/doc/VisGUI.rst:157: WARNING: undefined label: sec:intqt (if the link has no caption the label must precede a section header)
WARNING: html_static_path entry u'/Users/david/python-microscopy/doc/_static' does not exist
